Workbook

Sheet Resumen
B1: Genomma Lab Internacional
B2: TIPOS DE CAMBIO DE DÓLAR ESTADOUNIDENSE A MODENA LOCAL POR PAÍS
B3: ( * ) En el caso de Paraguay y Uruguay M.L. a Reales]
B4: Para el cierre de Marzo de 2026
C5: =C6&C8 -> MÉXICOBG | D5: =C6&D8 -> MÉXICOER | F5: =F6&F8 -> ESPAÑABG | G5: =F6&G8 -> ESPAÑAER | I5: =I6&I8 -> ARGENTINABG | J5: =I6&J8 -> ARGENTINAER | L5: =L6&L8 -> BOLIVIABG | M5: =L6&M8 -> BOLIVIAER | O5: =O6&O8 -> BRASILBG | P5: =O6&P8 -> BRASILER | R5: =R6&R8 -> CHILEBG | S5: =R6&S8 -> CHILEER | U5: =U6&U8 -> COLOMBIABG | V5: =U6&V8 -> COLOMBIAER | X5: =X6&X8 -> PARAGUAYBG | Y5: =X6&Y8 -> PARAGUAYER | AA5: ( * ) | AB5: =AA6&AB8 -> PARAGUAY [REAL]ER | AD5: =AD6&AD8 -> PERÚBG | AE5: =AD6&AE8 -> PERÚER | AG5: =AG6&AG8 -> URUGUAYBG | AH5: =AG6&AH8 -> URUGUAYER | AJ5: ( * ) | AK5: =AJ6&AK8 -> URUGUAY [REAL]ER | AM5: =AM6&AM8 -> COSTA RICABG | AN5: =AM6&AN8 -> COSTA RICAER | AP5: =AP6&AP8 -> DOMINICANABG | AQ5: =AP6&AQ8 -> DOMINICANAER | AS5: =AS6&AS8 -> PANAMÁBG | AT5: =AS6&AT8 -> PANAMÁER | AV5: =AV6&AV8 -> GUATEMALABG | AW5: =AV6&AW8 -> GUATEMALAER | AY5: =AY6&AY8 -> EL SALVADORBG | AZ5: =AY6&AZ8 -> EL SALVADORER | BB5: =BB6&BB8 -> HONDURASBG | BC5: =BB6&BC8 -> HONDURASER | BE5: =BE6&BE8 -> NICARAGUABG | BF5: =BE6&BF8 -> NICARAGUAER | BH5: =BH6&BH8 -> TRINIDAD Y TOBAGOBG | BI5: =BH6&BI8 -> TRINIDAD Y TOBAGOER
C6: MÉXICO | F6: ESPAÑA | I6: ARGENTINA | L6: BOLIVIA | O6: BRASIL | R6: CHILE | U6: COLOMBIA | X6: PARAGUAY | AA6: PARAGUAY [REAL] | AD6: PERÚ | AG6: URUGUAY | AJ6: URUGUAY [REAL] | AM6: COSTA RICA | AP6: DOMINICANA | AS6: PANAMÁ | AV6: GUATEMALA | AY6: EL SALVADOR | BB6: HONDURAS | BE6: NICARAGUA | BH6: TRINIDAD Y TOBAGO
C7: PESO | F7: EURO | I7: PESO | L7: BOLIVIANO | O7: REAL | R7: PESO | U7: PESO | X7: GUARANÍ | AA7: GUARANÍ | AD7: NUEVO SOL | AG7: PESO | AJ7: PESO | AM7: COLÓN | AP7: PESO | AS7: BALBOA | AV7: QUETZAL | AY7: COLÓN | BB7: LEMPIRA | BE7: CÓRDOBA | BH7: DÓLAR
B8: FECHA | C8: BG | D8: ER | F8: BG | G8: ER | I8: BG | J8: ER | L8: BG | M8: ER | O8: BG | P8: ER | R8: BG | S8: ER | U8: BG | V8: ER | X8: BG | Y8: ER | AA8: BG | AB8: ER | AD8: BG | AE8: ER | AG8: BG | AH8: ER | AJ8: BG | AK8: ER | AM8: BG | AN8: ER | AP8: BG | AQ8: ER | AS8: BG | AT8: ER | AV8: BG | AW8: ER | AY8: BG | AZ8: ER | BB8: BG | BC8: ER | BE8: BG | BF8: ER | BH8: BG | BI8: ER
C9: =COLUMN() -> 3 | D9: =COLUMN() -> 4 | F9: =COLUMN() -> 6 | G9: =COLUMN() -> 7 | I9: =COLUMN() -> 9 | J9: =COLUMN() -> 10 | L9: =COLUMN() -> 12 | M9: =COLUMN() -> 13 | O9: =COLUMN() -> 15 | P9: =COLUMN() -> 16 | R9: =COLUMN() -> 18 | S9: =COLUMN() -> 19 | U9: =COLUMN() -> 21 | V9: =COLUMN() -> 22 | X9: =COLUMN() -> 24 | Y9: =COLUMN() -> 25 | AA9: =COLUMN() -> 27 | AB9: =COLUMN() -> 28 | AD9: =COLUMN() -> 30 | AE9: =COLUMN() -> 31 | AG9: =COLUMN() -> 33 | AH9: =COLUMN() -> 34 | AJ9: =COLUMN() -> 36 | AK9: =COLUMN() -> 37 | AM9: =COLUMN() -> 39 | AN9: =COLUMN() -> 40 | AP9: =COLUMN() -> 42 | AQ9: =COLUMN() -> 43 | AS9: =COLUMN() -> 45 | AT9: =COLUMN() -> 46 | AV9: =COLUMN() -> 48 | AW9: =COLUMN() -> 49 | AY9: =COLUMN() -> 51 | AZ9: =COLUMN() -> 52 | BB9: =COLUMN() -> 54 | BC9: =COLUMN() -> 55 | BE9: =COLUMN() -> 57 | BF9: =COLUMN() -> 58 | BH9: =COLUMN() -> 60 | BI9: =COLUMN() -> 61
A10: Dic-16 | B10: 42735 | C10: 20.664 | D10: 20.5199 | F10: 0.950539 | G10: 0.948915 | I10: 15.9681 | J10: 15.8584 | L10: 6.93335 | M10: 6.92731 | O10: 3.25542 | P10: 3.35884 | R10: 669.074 | S10: 667.183 | U10: 3009.53 | V10: 3012.94 | X10: 5786.5 | Y10: 5803.31 | AA10: 1777.53 | AB10: 1728.4 | AD10: 3.3699 | AE10: 3.39835 | AG10: 29.193 | AH10: 28.75275 | AJ10: 8.9677 | AK10: 8.56363 | AM10: 552.87 | AN10: 551.335 | AP10: 46.698 | AQ10: 46.5188 | AS10: 1 | AT10: 1 | AV10: 7.54755 | AW10: 7.50934 | AY10: 8.77995 | AZ10: 8.75081 | BB10: 23.359 | BC10: 23.27465 | BE10: 29.56 | BF10: 29.28337 | BH10: 6.74275 | BI10: 6.73319
A11: Ene-17 | B11: 42766 | C11: 20.7588 | D11: 21.3368 | F11: 0.931845 | G11: 0.941137 | I11: 15.9099 | J11: 15.8922 | L11: 6.91583 | M11: 6.92173 | O11: 3.13169 | P11: 3.19856 | R11: 647.716 | S11: 660.369 | U11: 2924.13 | V11: 2942.94 | X11: 5769.2 | Y11: 5754.05 | AA11: 1842.22 | AB11: 1799.19 | AD11: 3.28191 | AE11: 3.33958 | AG11: 28.1136 | AH11: 28.6313 | AJ11: 8.9772 | AK11: 8.95158 | AM11: 549.874 | AN11: 551.411 | AP11: 46.5725 | AQ11: 46.5294 | AS11: 1 | AT11: 1 | AV11: 7.45866 | AW11: 7.52057 | AY11: 8.73157 | AZ11: 8.74615 | BB11: 23.5669 | BC11: 23.32938 | BE11: 29.358 | BF11: 29.38383 | BH11: 6.71785 | BI11: 6.7244
A12: Feb-17 | B12: 42794 | C12: 19.8322 | D12: 20.2911 | F12: 0.943882 | G12: 0.939287 | I12: 15.4749 | J12: 15.5836 | L12: 6.9316 | M12: 6.92177 | O12: 3.10908 | P12: 3.10668 | R12: 647.961 | S12: 643.259 | U12: 2910.97 | V12: 2875.88 | X12: 5537.49 | Y12: 5698.65 | AA12: 1781.09 | AB12: 1834.34 | AD12: 3.25746 | AE12: 3.259 | AG12: 28.2561 | AH12: 28.3224 | AJ12: 9.08831 | AK12: 9.1171 | AM12: 557.627 | AN12: 556.78 | AP12: 47.1033 | AQ12: 46.8546 | AS12: 1 | AT12: 1 | AV12: 7.36235 | AW12: 7.41416 | AY12: 8.75211 | AZ12: 8.75103 | BB12: 23.5225 | BC12: 23.5544 | BE12: 29.5986 | BF12: 29.5163 | BH12: 6.72282 | BI12: 6.73017
A13: Mar-17 | B13: 42825 | C13: 18.7079 | D13: 19.2962 | F13: 0.936128 | G13: 0.93533 | I13: 15.4096 | J13: 15.52 | L13: 6.94987 | M13: 6.92173 | O13: 3.14828 | P13: 3.1234 | R13: 662.707 | S13: 661.144 | U13: 2885.07 | V13: 2941.56 | X13: 5765.77 | Y13: 5514.91 | AA13: 1831.42 | AB13: 1765.85 | AD13: 3.25442 | AE13: 3.26253 | AG13: 28.63021 | AH13: 28.2312 | AJ13: 9.09399 | AK13: 9.03911 | AM13: 558.13 | AN13: 557.529 | AP13: 47.2677 | AQ13: 47.1025 | AS13: 1 | AT13: 1 | AV13: 7.35607 | AW13: 7.35216 | AY13: 8.77567 | AZ13: 8.73959 | BB13: 23.42085 | BC13: 23.49069 | BE13: 29.67729 | BF13: 29.55118 | BH13: 6.75078 | BI13: 6.72359
A14: Abr-17 | B14: 42855 | C14: 19.067 | D14: 18.7437 | F14: 0.917751 | G14: 0.93401 | I14: 15.3884 | J14: 15.3443 | L14: 6.97705 | M14: 6.93165 | O14: 3.17674 | P14: 3.14039 | R14: 667.1 | S14: 655.732 | U14: 2941.89 | V14: 2876.11 | X14: 5601.8 | Y14: 5612.81 | AA14: 1763.41 | AB14: 1787.45 | AD14: 3.25815 | AE14: 3.24905 | AG14: 28.224 | AH14: 28.4752 | AJ14: 8.88474 | AK14: 9.06806 | AM14: 560.67 | AN14: 557.546 | AP14: 47.444 | AQ14: 47.2115 | AS14: 1 | AT14: 1 | AV14: 7.37205 | AW14: 7.33937 | AY14: 8.78395 | AZ14: 8.75074 | BB14: 23.5315 | BC14: 23.42151 | BE14: 29.695 | BF14: 29.6118 | BH14: 6.75615 | BI14: 6.73454
A15: May-17 | B15: 42886 | C15: 18.6643 | D15: 18.7688 | F15: 0.892766 | G15: 0.904625 | I15: 16.139 | J15: 15.6853 | L15: 6.94117 | M15: 6.94176 | O15: 3.2521 | P15: 3.20454 | R15: 673.617 | S15: 671.407 | U15: 2913.38 | V15: 2923.88 | X15: 5585.7 | Y15: 5603.25 | AA15: 1717.59 | AB15: 1749.12 | AD15: 3.273 | AE15: 3.27096 | AG15: 28.27093 | AH15: 28.10058 | AJ15: 8.69322 | AK15: 8.7717 | AM15: 574.385 | AN15: 568.53 | AP15: 47.1798 | AQ15: 47.2354 | AS15: 1 | AT15: 1 | AV15: 7.34015 | AW15: 7.33521 | AY15: 8.73872 | AZ15: 8.74389 | BB15: 23.49631 | BC15: 23.45267 | BE15: 29.79591 | BF15: 29.73893 | BH15: 6.72142 | BI15: 6.73013
A16: Jun-17 | B16: 42916 | C16: 18.0279 | D16: 18.1592 | F16: 0.875404 | G16: 0.890647 | I16: 16.5272 | J16: 16.0842 | L16: 6.92966 | M16: 6.94244 | O16: 3.30589 | P16: 3.29223 | R16: 664.562 | S16: 665.111 | U16: 3034.74 | V16: 2960.75 | X16: 5562.91 | Y16: 5576.14 | AA16: 1682.75 | AB16: 1693.89 | AD16: 3.24408 | AE16: 3.26522 | AG16: 28.3252 | AH16: 28.33388 | AJ16: 8.56817 | AK16: 8.60701 | AM16: 567.065 | AN16: 568.248 | AP16: 47.2574 | AQ16: 47.2841 | AS16: 1 | AT16: 1 | AV16: 7.32498 | AW16: 7.33964 | AY16: 8.73577 | AZ16: 8.74121 | BB16: 23.32902 | BC16: 23.43096 | BE16: 29.86933 | BF16: 29.78087 | BH16: 6.72548 | BI16: 6.72675
A17: Jul-17 | B17: 42947 | C17: 17.7435 | D17: 17.8294 | F17: 0.849664 | G17: 0.867682 | I17: 17.7399 | J17: 17.1425 | L17: 6.94238 | M17: 6.94816 | O17: 3.12989 | P17: 3.20667 | R17: 652.192 | S17: 657.969 | U17: 2996.88 | V17: 3036.57 | X17: 5544.65 | Y17: 5547.41 | AA17: 1771.53 | AB17: 1730.66 | AD17: 3.23879 | AE17: 3.24468 | AG17: 28.30959 | AH17: 28.59489 | AJ17: 9.04498 | AK17: 8.9207 | AM17: 572.755 | AN17: 571.307 | AP17: 47.1972 | AQ17: 47.2921 | AS17: 1 | AT17: 1 | AV17: 7.27308 | AW17: 7.30013 | AY17: 8.72793 | AZ17: 8.73672 | BB17: 23.39159 | BC17: 23.41349 | BE17: 29.94102 | BF17: 29.9629 | BH17: 6.72819 | BI17: 6.7401
A18: Ago-17 | B18: 42978 | C18: 17.7753 | D18: 17.7957 | F18: 0.841538 | G18: 0.84632 | I18: 17.3708 | J18: 17.4198 | L18: 6.97353 | M18: 6.95573 | O18: 3.15462 | P18: 3.1536 | R18: 629.464 | S18: 643.6 | U18: 2951.25 | V18: 2970.18 | X18: 5669.71 | Y18: 5581.3 | AA18: 1797.29 | AB18: 1769.92 | AD18: 3.24458 | AE18: 3.239 | AG18: 28.77583 | AH18: 28.60856 | AJ18: 9.12185 | AK18: 9.07195 | AM18: 577.31 | AN18: 576.178 | AP18: 47.3054 | AQ18: 47.1953 | AS18: 1 | AT18: 1 | AV18: 7.30401 | AW18: 7.26887 | AY18: 8.76916 | AZ18: 8.7416 | BB18: 23.43104 | BC18: 23.36501 | BE18: 29.97362 | BF18: 29.91742 | BH18: 6.74253 | BI18: 6.75064
A19: Sep-17 | B19: 43008 | C19: 18.1979 | D19: 17.8208 | F19: 0.846418 | G19: 0.839141 | I19: 17.634 | J19: 17.2557 | L19: 7.0072 | M19: 6.96949 | O19: 3.1631 | P19: 3.13107 | R19: 640.1 | S19: 625.868 | U19: 2961.3 | V19: 2918.45 | X19: 5689.4 | Y19: 5667.48 | AA19: 1798.7 | AB19: 1810.21 | AD19: 3.28665 | AE19: 3.24837 | AG19: 29.322 | AH19: 28.92333 | AJ19: 9.27013 | AK19: 9.23806 | AM19: 575.785 | AN19: 577.041 | AP19: 48.0595 | AQ19: 47.4349 | AS19: 1 | AT19: 1 | AV19: 7.37895 | AW19: 7.30802 | AY19: 8.803 | AZ19: 8.76102 | BB19: 23.55 | BC19: 23.42127 | BE19: 30.544 | BF19: 30.31597 | BH19: 6.79375 | BI19: 6.76605
A20: Oct-17 | B20: 43039 | C20: 19.2188 | D20: 18.8157 | F20: 0.858978 | G20: 0.850859 | I20: 17.6769 | J20: 17.4528 | L20: 6.91713 | M20: 6.9189 | O20: 3.2814 | P20: 3.18813 | R20: 635.65 | S20: 630.363 | U20: 3022.68 | V20: 2954.99 | X20: 5644.33 | Y20: 5647.77 | AA20: 1720.11 | AB20: 1771.82 | AD20: 3.24594 | AE20: 3.25186 | AG20: 29.31657 | AH20: 29.36767 | AJ20: 8.93421 | AK20: 9.21269 | AM20: 569.516 | AN20: 571.776 | AP20: 47.9716 | AQ20: 47.6892 | AS20: 1 | AT20: 1 | AV20: 7.34831 | AW20: 7.35144 | AY20: 8.74457 | AZ20: 8.75448 | BB20: 23.57032 | BC20: 23.49299 | BE20: 30.65391 | BF20: 30.50783 | BH20: 6.73118 | BI20: 6.74601
A21: Nov-17 | B21: 43069 | C21: 18.519 | D21: 18.9346 | F21: 0.842238 | G21: 0.851788 | I21: 17.384 | J21: 17.4885 | L21: 6.94597 | M21: 6.93721 | O21: 3.25769 | P21: 3.26369 | R21: 645.174 | S21: 633.162 | U21: 3001.07 | V21: 3014.21 | X21: 5658.02 | Y21: 5652.05 | AA21: 1736.83 | AB21: 1731.94 | AD21: 3.23023 | AE21: 3.24369 | AG21: 28.96244 | AH21: 29.26911 | AJ21: 8.89053 | AK21: 8.96875 | AM21: 565.394 | AN21: 567.899 | AP21: 48.0762 | AQ21: 47.9958 | AS21: 1 | AT21: 1 | AV21: 7.3437 | AW21: 7.34182 | AY21: 8.75 | AZ21: 8.74601 | BB21: 23.61179 | BC21: 23.6116 | BE21: 30.76391 | BF21: 30.71456 | BH21: 6.72681 | BI21: 6.73504
... A51: May-20 | B51: 43982 | C51: 22.204 | D51: 23.5224 | F51: 0.900423 | G51: 0.916603 | I51: 68.4618 | J51: 67.6131 | L51: 6.90302 | M51: 6.8958 | O51: 5.33765 | P51: 5.61872 | R51: 799.023 | S51: 820.872 | U51: 3729.96 | V51: 3860.61 | X51: 6636.35 | Y51: 6563.8 | AA51: 1243.32 | AB51: 1169.58 | AD51: 3.42815 | AE51: 3.41456 | AG51: 43.24343 | AH51: 43.32703 | AJ51: 8.10161 | AK51: 7.71759 | AM51: 569.376 | AN51: 568.393 | AP51: 56.205 | AQ51: 55.2093 | AS51: 1 | AT51: 1 | AV51: 7.68593 | AW51: 7.69713 | AY51: 8.75 | AZ51: 8.75 | BB51: 24.89073 | BC51: 24.87315 | BE51: 34.17475 | BF51: 34.22346 | BH51: 6.75494 | BI51: 6.74853
B52: 44012 | C52: 23.1325 | D52: 22.3001 | F52: 0.890554 | G52: 0.8888 | I52: 70.3871 | J52: 69.4815 | L52: 6.93317 | M52: 6.9079 | O52: 5.43142 | P52: 5.1909 | R52: 821.428 | S52: 796.77 | U52: 3750.25 | V52: 3708.24 | X52: 6786.92 | Y52: 6690.37 | AA52: 1249.57 | AB52: 1290.29 | AD52: 3.53753 | AE52: 3.4725 | AG52: 42.16045 | AH52: 42.717 | AJ52: 7.76235 | AK52: 8.2406 | AM52: 581.19 | AN52: 576.307 | AP52: 58.4835 | AQ52: 57.9659 | AS52: 1 | AT52: 1 | AV52: 7.71858 | AW52: 7.6944 | AY52: 8.75 | AZ52: 8.75 | BB52: 24.86765 | BC52: 24.8468 | BE52: 34.23748 | BF52: 34.136 | BH52: 6.77871 | BI52: 6.7597
B53: 44043 | C53: 22.1727 | D53: 22.4493 | F53: 0.844764 | G53: 0.873535 | I53: 72.29569 | J53: 71.308192 | L53: 6.89042 | M53: 6.90294 | O53: 5.181816 | P53: 5.293533 | R53: 759.412 | S53: 784.956 | U53: 3726.21 | V53: 3657.32 | X53: 6929.3 | Y53: 6872.45 | AA53: 1337.24 | AB53: 1298.71 | AD53: 3.50999 | AE53: 3.51481 | AG53: 42.36194 | AH53: 43.04087 | AJ53: 8.17514 | AK53: 8.13211 | AM53: 580.8145 | AN53: 581.632 | AP53: 58.4151 | AQ53: 58.4457 | AS53: 1 | AT53: 1 | AV53: 7.684498 | AW53: 7.69471 | AY53: 8.75 | AZ53: 8.75 | BB53: 24.69878 | BC53: 24.78767 | BE53: 34.47462 | BF53: 34.56219 | BH53: 6.74459 | BI53: 6.75601
B54: 44074 | C54: 21.8602 | D54: 22.221 | F54: 0.83863 | G54: 0.845565 | I54: 74.0208 | J54: 73.196347 | L54: 6.89675 | M54: 6.9043 | O54: 5.43277 | P54: 5.442449 | R54: 778.035 | S54: 784.927 | U54: 3744.58 | V54: 3780.84 | X54: 6967.67 | Y54: 6946.26 | AA54: 1282.53 | AB54: 1276.83 | AD54: 3.5418 | AE54: 3.56118 | AG54: 42.67344 | AH54: 42.67694 | AJ54: 7.85485 | AK54: 7.8444 | AM54: 594.8718 | AN54: 590.9072 | AP54: 58.3912 | AQ54: 58.4944 | AS54: 1 | AT54: 1 | AV54: 7.707494 | AW54: 7.7025 | AY54: 8.75 | AZ54: 8.75 | BB54: 24.6506 | BC54: 24.70088 | BE54: 34.84854 | BF54: 34.75763 | BH54: 6.77468 | BI54: 6.76851
B55: 44104 | C55: 22.3598 | D55: 21.6218 | F55: 0.852905 | G55: 0.8482 | I55: 76.1415 | J55: 75.1107 | L55: 6.89566 | M55: 6.908 | O55: 5.629122 | P55: 5.3955 | R55: 785.481 | S55: 773.387 | U55: 3866.93 | V55: 3753.6 | X55: 6967.75 | Y55: 6984.11 | AA55: 1237.81 | AB55: 1295.07 | AD55: 3.58835 | AE55: 3.5559 | AG55: 42.46137 | AH55: 42.5206 | AJ55: 7.54318 | AK55: 7.8848 | AM55: 602.1843 | AN55: 597.5002 | AP55: 58.3241 | AQ55: 58.4644 | AS55: 1 | AT55: 1 | AV55: 7.771779 | AW55: 7.7555 | AY55: 8.75 | AZ55: 8.75 | BB55: 24.59609 | BC55: 24.6824 | BE55: 34.72725 | BF55: 34.77 | BH55: 6.78655 | BI55: 6.7801
B56: 44135 | C56: 21.377 | D56: 21.3491 | F56: 0.858516 | G56: 0.8498 | I56: 78.33315 | J56: 77.4927 | L56: 6.90735 | M56: 6.9053 | O56: 5.7423 | P56: 5.6222 | R56: 773.3 | S56: 788.621 | U56: 3869.2 | V56: 3833.1 | X56: 7031.65 | Y56: 7010.08 | AA56: 1224.54 | AB56: 1247 | AD56: 3.61585 | AE56: 3.5959 | AG56: 43.03 | AH56: 42.6496 | AJ56: 7.49355 | AK56: 7.5867 | AM56: 606.17 | AN56: 603.1793 | AP56: 58.5 | AQ56: 58.4337 | AS56: 1 | AT56: 1 | AV56: 7.7888 | AW56: 7.7804 | AY56: 8.75 | AZ56: 8.75 | BB56: 24.5822 | BC56: 24.6084 | BE56: 34.8055 | BF56: 34.7771 | BH56: 6.80365 | BI56: 6.7834
B57: 44165 | C57: 20.0777 | D57: 20.49 | F57: 0.835776 | G57: 0.8446 | I57: 81.02876 | J57: 79.8216 | L57: 6.8905 | M57: 6.8978 | O57: 5.343163 | P57: 5.439 | R57: 766.882 | S57: 762.909 | U57: 3600.64 | V57: 3679.47 | X57: 7036.87 | Y57: 7032.96 | AA57: 1316.99 | AB57: 1293.8 | AD57: 3.60025 | AE57: 3.6084 | AG57: 42.58285 | AH57: 42.7869 | AJ57: 7.96963 | AK57: 7.8707 | AM57: 601.8521 | AN57: 609.0887 | AP57: 58.0846 | AQ57: 58.2044 | AS57: 1 | AT57: 1 | AV57: 7.798095 | AW57: 7.7888 | AY57: 8.75 | AZ57: 8.75 | BB57: 24.22724 | BC57: 24.4653 | BE57: 34.80626 | BF57: 34.891 | BH57: 6.77787 | BI57: 6.7889
B58: 44196 | C58: 19.9352 | D58: 19.9736 | F58: 0.815352 | G58: 0.8218 | I58: 84.11626 | J58: 82.5178 | L58: 6.88059 | M58: 6.8915 | O58: 5.193965 | P58: 5.1486 | R58: 710.672 | S58: 731.193 | U58: 3433.23 | V58: 3465.42 | X58: 6911.21 | Y58: 6980.77 | AA58: 1330.63 | AB58: 1356.13 | AD58: 3.61167 | AE58: 3.5997 | AG58: 42.14966 | AH58: 42.4225 | AJ58: 8.11516 | AK58: 8.241 | AM58: 609.0522 | AN58: 604.86 | AP58: 58.065 | AQ58: 58.159 | AS58: 1 | AT58: 1 | AV58: 7.787147 | AW58: 7.8034 | AY58: 8.75 | AZ58: 8.75 | BB58: 24.12569 | BC58: 24.2007 | BE58: 34.83751 | BF58: 34.8454 | BH58: 6.76818 | BI58: 6.7911
B59: 44227 | C59: 20.2697 | D59: 19.9134 | F59: 0.823946 | G59: 0.8216 | I59: 87.2838 | J59: 85.831 | L59: 6.89786 | M59: 6.8872 | O59: 5.463 | P59: 5.3523 | R59: 734.81 | S59: 723.232 | U59: 3569.23 | V59: 3492.52 | X59: 6955.33 | Y59: 6906.43 | AA59: 1273.18 | AB59: 1290.75 | AD59: 3.63773 | AE59: 3.6252 | AG59: 42.23427 | AH59: 42.311 | AJ59: 7.73099 | AK59: 7.9077 | AM59: 612.5901 | AN59: 611.9464 | AP59: 58.0325 | AQ59: 58.1919 | AS59: 1 | AT59: 1 | AV59: 7.773892 | AW59: 7.7924 | AY59: 8.75 | AZ59: 8.75 | BB59: 24.18263 | BC59: 24.165 | BE59: 35.02975 | BF59: 34.9613 | BH59: 6.79776 | BI59: 6.7894
B60: 44255 | C60: 20.8523 | D60: 20.3133 | F60: 0.828318 | G60: 0.8268 | I60: 89.82191 | J60: 88.6366 | L60: 6.89668 | M60: 6.9046 | O60: 5.5989 | P60: 5.4145 | R60: 724.148 | S60: 722.615 | U60: 3646.48 | V60: 3558.13 | X60: 6617.71 | Y60: 6775.23 | AA60: 1181.97 | AB60: 1251.62 | AD60: 3.64842 | AE60: 3.645 | AG60: 43.11363 | AH60: 42.6657 | AJ60: 7.7004 | AK60: 7.8806 | AM60: 611.5814 | AN60: 611.8587 | AP60: 57.8444 | AQ60: 57.9591 | AS60: 1 | AT60: 1 | AV60: 7.70361 | AW60: 7.7462 | AY60: 8.75 | AZ60: 8.75 | BB60: 24.0831 | BC60: 24.1346 | BE60: 34.88517 | BF60: 34.9396 | BH60: 6.78654 | BI60: 6.7839
B61: 44286 | C61: 20.6025 | D61: 20.754 | F61: 0.85268 | G61: 0.8404 | I61: 91.96546 | J61: 91.0214 | L61: 6.91182 | M61: 6.9073 | O61: 5.720229 | P61: 5.6378 | R61: 724.864 | S61: 726.045 | U61: 3701.58 | V61: 3616.31 | X61: 6450.21 | Y61: 6590.36 | AA61: 1127.62 | AB61: 1169.32 | AD61: 3.76442 | AE61: 3.7054 | AG61: 44.51188 | AH61: 44.2013 | AJ61: 7.78151 | AK61: 7.8426 | AM61: 613.3149 | AN61: 611.7779 | AP61: 56.9342 | AQ61: 57.3845 | AS61: 1 | AT61: 1 | AV61: 7.719384 | AW61: 7.7178 | AY61: 8.75 | AZ61: 8.75 | BB61: 24.06459 | BC61: 24.1287 | BE61: 35.01031 | BF61: 35.0034 | BH61: 6.79509 | BI61: 6.7924
B62: 44316 | C62: 20.0978 | D62: 20.0926 | F62: 0.828278 | G62: 0.8366 | I62: 93.50909 | J62: 92.6314 | L62: 6.90365 | M62: 6.9013 | O62: 5.377791 | P62: 5.583 | R62: 710.015 | S62: 708.922 | U62: 3726.67 | V62: 3651.59 | X62: 6496.62 | Y62: 6394.81 | AA62: 1208.05 | AB62: 1145.99 | AD62: 3.78517 | AE62: 3.6962 | AG62: 43.98472 | AH62: 44.1555 | AJ62: 8.17898 | AK62: 7.9116 | AM62: 615.9831 | AN62: 613.3575 | AP62: 56.8432 | AQ62: 56.8706 | AS62: 1 | AT62: 1 | AV62: 7.715278 | AW62: 7.7124 | AY62: 8.75 | AZ62: 8.75 | BB62: 24.0516 | BC62: 24.0493 | BE62: 35.07272 | BF62: 35.0147 | BH62: 6.7908 | BI62: 6.7859
B63: 44347 | C63: 19.9442 | D63: 19.9938 | F63: 0.819144 | G63: 0.8235 | I63: 94.55676 | J63: 94.042 | L63: 6.90335 | M63: 6.902 | O63: 5.229936 | P63: 5.3028 | R63: 723.532 | S63: 711.899 | U63: 3708.17 | V63: 3736.51 | X63: 6748.09 | Y63: 6688.17 | AA63: 1290.29 | AB63: 1261.61 | AD63: 3.82298 | AE63: 3.77 | AG63: 43.84292 | AH63: 44.0245 | AJ63: 8.3831 | AK63: 8.3036 | AM63: 617.644 | AN63: 616.5186 | AP63: 56.8676 | AQ63: 56.9299 | AS63: 1 | AT63: 1 | AV63: 7.723029 | AW63: 7.718 | AY63: 8.75 | AZ63: 8.75 | BB63: 24.02323 | BC63: 24.0521 | BE63: 35.00969 | BF63: 35.1095 | BH63: 6.79399 | BI63: 6.7915
... B106: 45657 | C106: 20.7862 | D106: 20.25569 | F106: 0.962722 | G106: 0.95460558 | I106: 1031 | J106: 1019.6448 | L106: 6.93563 | M106: 6.9115016 | O106: 6.18456 | P106: 6.1156465 | R106: 994.128 | S106: 983.10377 | U106: 4408.24 | V106: 4389.8568 | X106: 7821.84 | Y106: 7809.1726 | AA106: 1264.74 | AB106: 1277.2935 | AD106: 3.75724 | AE106: 3.7336158 | AG106: 43.8698 | AH106: 43.921123 | AJ106: 7.09346 | AK106: 7.1827968 | AM106: 508.124 | AN106: 505.71958 | AP106: 61.0842 | AQ106: 60.666048 | AS106: 1 | AT106: 1 | AV106: 7.72321 | AW106: 7.7081139 | AY106: 8.75 | AZ106: 8.75 | BB106: 25.4508 | BC106: 25.348687 | BE106: 36.8628 | BF106: 36.793619 | BH106: 6.80789 | BI106: 6.786221
B107: 45688 | C107: =VLOOKUP($B107,'BD_T.C.'!$B:$AO,HLOOKUP(C$6,'BD_T.C.'!$6:$7,2,FALSE),FALSE) -> 20.4497 | D107: =VLOOKUP("PROM-"&MONTH($B107)&YEAR($B107),'BD_T.C.'!$B:$AO,HLOOKUP(C$6,'BD_T.C.'!$6:$7,2,FALSE),FALSE) -> 20.571316 | F107: =VLOOKUP($B107,'BD_T.C.'!$B:$AO,HLOOKUP(F$6,'BD_T.C.'!$6:$7,2,FALSE),FALSE) -> 0.96306 | G107: =VLOOKUP("PROM-"&MONTH($B107)&YEAR($B107),'BD_T.C.'!$B:$AO,HLOOKUP(F$6,'BD_T.C.'!$6:$7,2,FALSE),FALSE) -> 0.96639058 | I107: =VLOOKUP($B107,'BD_T.C.'!$B:$AO,HLOOKUP(I$6,'BD_T.C.'!$6:$7,2,FALSE),FALSE) -> 1051.16 | J107: =VLOOKUP("PROM-"&MONTH($B107)&YEAR($B107),'BD_T.C.'!$B:$AO,HLOOKUP(I$6,'BD_T.C.'!$6:$7,2,FALSE),FALSE) -> 1040.9161 | L107: =VLOOKUP($B107,'BD_T.C.'!$B:$AO,HLOOKUP(L$6,'BD_T.C.'!$6:$7,2,FALSE),FALSE) -> 6.91037 | M107: =VLOOKUP("PROM-"&MONTH($B107)&YEAR($B107),'BD_T.C.'!$B:$AO,HLOOKUP(L$6,'BD_T.C.'!$6:$7,2,FALSE),FALSE) -> 6.9146184 | O107: =VLOOKUP($B107,'BD_T.C.'!$B:$AO,HLOOKUP(O$6,'BD_T.C.'!$6:$7,2,FALSE),FALSE) -> 5.8595 | P107: =VLOOKUP("PROM-"&MONTH($B107)&YEAR($B107),'BD_T.C.'!$B:$AO,HLOOKUP(O$6,'BD_T.C.'!$6:$7,2,FALSE),FALSE) -> 6.0444326 | R107: =VLOOKUP($B107,'BD_T.C.'!$B:$AO,HLOOKUP(R$6,'BD_T.C.'!$6:$7,2,FALSE),FALSE) -> 983.953 | S107: =VLOOKUP("PROM-"&MONTH($B107)&YEAR($B107),'BD_T.C.'!$B:$AO,HLOOKUP(R$6,'BD_T.C.'!$6:$7,2,FALSE),FALSE) -> 1000.9617 | U107: =VLOOKUP($B107,'BD_T.C.'!$B:$AO,HLOOKUP(U$6,'BD_T.C.'!$6:$7,2,FALSE),FALSE) -> 4176.38 | V107: =VLOOKUP("PROM-"&MONTH($B107)&YEAR($B107),'BD_T.C.'!$B:$AO,HLOOKUP(U$6,'BD_T.C.'!$6:$7,2,FALSE),FALSE) -> 4298.0839 | X107: =VLOOKUP($B107,'BD_T.C.'!$B:$AO,HLOOKUP(X$6,'BD_T.C.'!$6:$7,2,FALSE),FALSE) -> 7892.21 | Y107: =VLOOKUP("PROM-"&MONTH($B107)&YEAR($B107),'BD_T.C.'!$B:$AO,HLOOKUP(X$6,'BD_T.C.'!$6:$7,2,FALSE),FALSE) -> 7874.8326 | AA107: =VLOOKUP($B107,'BD_T.C.'!$B:$AO,HLOOKUP(AA$6,'BD_T.C.'!$6:$7,2,FALSE),FALSE) -> 1346.92 | AB107: =VLOOKUP("PROM-"&MONTH($B107)&YEAR($B107),'BD_T.C.'!$B:$AO,HLOOKUP(AA$6,'BD_T.C.'!$6:$7,2,FALSE),FALSE) -> 1303.3268 | AD107: =VLOOKUP($B107,'BD_T.C.'!$B:$AO,HLOOKUP(AD$6,'BD_T.C.'!$6:$7,2,FALSE),FALSE) -> 3.72044 | AE107: =VLOOKUP("PROM-"&MONTH($B107)&YEAR($B107),'BD_T.C.'!$B:$AO,HLOOKUP(AD$6,'BD_T.C.'!$6:$7,2,FALSE),FALSE) -> 3.7493403 | AG107: =VLOOKUP($B107,'BD_T.C.'!$B:$AO,HLOOKUP(AG$6,'BD_T.C.'!$6:$7,2,FALSE),FALSE) -> 43.3438 | AH107: =VLOOKUP("PROM-"&MONTH($B107)&YEAR($B107),'BD_T.C.'!$B:$AO,HLOOKUP(AG$6,'BD_T.C.'!$6:$7,2,FALSE),FALSE) -> 43.799342 | AJ107: =VLOOKUP($B107,'BD_T.C.'!$B:$AO,HLOOKUP(AJ$6,'BD_T.C.'!$6:$7,2,FALSE),FALSE) -> 7.3972 | AK107: =VLOOKUP("PROM-"&MONTH($B107)&YEAR($B107),'BD_T.C.'!$B:$AO,HLOOKUP(AJ$6,'BD_T.C.'!$6:$7,2,FALSE),FALSE) -> 7.2480742 | AM107: =VLOOKUP($B107,'BD_T.C.'!$B:$AO,HLOOKUP(AM$6,'BD_T.C.'!$6:$7,2,FALSE),FALSE) -> 506.08 | AN107: =VLOOKUP("PROM-"&MONTH($B107)&YEAR($B107),'BD_T.C.'!$B:$AO,HLOOKUP(AM$6,'BD_T.C.'!$6:$7,2,FALSE),FALSE) -> 506.17842 | AP107: =VLOOKUP($B107,'BD_T.C.'!$B:$AO,HLOOKUP(AP$6,'BD_T.C.'!$6:$7,2,FALSE),FALSE) -> 61.7737 | AQ107: =VLOOKUP("PROM-"&MONTH($B107)&YEAR($B107),'BD_T.C.'!$B:$AO,HLOOKUP(AP$6,'BD_T.C.'!$6:$7,2,FALSE),FALSE) -> 61.39581 | AS107: =VLOOKUP($B107,'BD_T.C.'!$B:$AO,HLOOKUP(AS$6,'BD_T.C.'!$6:$7,2,FALSE),FALSE) -> 1 | AT107: =VLOOKUP("PROM-"&MONTH($B107)&YEAR($B107),'BD_T.C.'!$B:$AO,HLOOKUP(AS$6,'BD_T.C.'!$6:$7,2,FALSE),FALSE) -> 1 | AV107: =VLOOKUP($B107,'BD_T.C.'!$B:$AO,HLOOKUP(AV$6,'BD_T.C.'!$6:$7,2,FALSE),FALSE) -> 7.73749 | AW107: =VLOOKUP("PROM-"&MONTH($B107)&YEAR($B107),'BD_T.C.'!$B:$AO,HLOOKUP(AV$6,'BD_T.C.'!$6:$7,2,FALSE),FALSE) -> 7.7232874 | AY107: =VLOOKUP($B107,'BD_T.C.'!$B:$AO,HLOOKUP(AY$6,'BD_T.C.'!$6:$7,2,FALSE),FALSE) -> 8.75 | AZ107: =VLOOKUP("PROM-"&MONTH($B107)&YEAR($B107),'BD_T.C.'!$B:$AO,HLOOKUP(AY$6,'BD_T.C.'!$6:$7,2,FALSE),FALSE) -> 8.75 | BB107: =VLOOKUP($B107,'BD_T.C.'!$B:$AO,HLOOKUP(BB$6,'BD_T.C.'!$6:$7,2,FALSE),FALSE) -> 25.5346 | BC107: =VLOOKUP("PROM-"&MONTH($B107)&YEAR($B107),'BD_T.C.'!$B:$AO,HLOOKUP(BB$6,'BD_T.C.'!$6:$7,2,FALSE),FALSE) -> 25.469774 | BE107: =VLOOKUP($B107,'BD_T.C.'!$B:$AO,HLOOKUP(BE$6,'BD_T.C.'!$6:$7,2,FALSE),FALSE) -> 36.7716 | BF107: =VLOOKUP("PROM-"&MONTH($B107)&YEAR($B107),'BD_T.C.'!$B:$AO,HLOOKUP(BE$6,'BD_T.C.'!$6:$7,2,FALSE),FALSE) -> 36.792568 | BH107: =VLOOKUP($B107,'BD_T.C.'!$B:$AO,HLOOKUP(BH$6,'BD_T.C.'!$6:$7,2,FALSE),FALSE) -> 6.78326 | BI107: =VLOOKUP("PROM-"&MONTH($B107)&YEAR($B107),'BD_T.C.'!$B:$AO,HLOOKUP(BH$6,'BD_T.C.'!$6:$7,2,FALSE),FALSE) -> 6.7924713
B108: 45716 | C108: =VLOOKUP($B108,'BD_T.C.'!$B:$AO,HLOOKUP(C$6,'BD_T.C.'!$6:$7,2,FALSE),FALSE) -> 20.4722 | D108: =VLOOKUP("PROM-"&MONTH($B108)&YEAR($B108),'BD_T.C.'!$B:$AO,HLOOKUP(C$6,'BD_T.C.'!$6:$7,2,FALSE),FALSE) -> 20.460739 | F108: =VLOOKUP($B108,'BD_T.C.'!$B:$AO,HLOOKUP(F$6,'BD_T.C.'!$6:$7,2,FALSE),FALSE) -> 0.962308 | G108: =VLOOKUP("PROM-"&MONTH($B108)&YEAR($B108),'BD_T.C.'!$B:$AO,HLOOKUP(F$6,'BD_T.C.'!$6:$7,2,FALSE),FALSE) -> 0.96040411 | I108: =VLOOKUP($B108,'BD_T.C.'!$B:$AO,HLOOKUP(I$6,'BD_T.C.'!$6:$7,2,FALSE),FALSE) -> 1062.42 | J108: =VLOOKUP("PROM-"&MONTH($B108)&YEAR($B108),'BD_T.C.'!$B:$AO,HLOOKUP(I$6,'BD_T.C.'!$6:$7,2,FALSE),FALSE) -> 1056.6889 | L108: =VLOOKUP($B108,'BD_T.C.'!$B:$AO,HLOOKUP(L$6,'BD_T.C.'!$6:$7,2,FALSE),FALSE) -> 6.9211 | M108: =VLOOKUP("PROM-"&MONTH($B108)&YEAR($B108),'BD_T.C.'!$B:$AO,HLOOKUP(L$6,'BD_T.C.'!$6:$7,2,FALSE),FALSE) -> 6.9136507 | O108: =VLOOKUP($B108,'BD_T.C.'!$B:$AO,HLOOKUP(O$6,'BD_T.C.'!$6:$7,2,FALSE),FALSE) -> 5.86331 | P108: =VLOOKUP("PROM-"&MONTH($B108)&YEAR($B108),'BD_T.C.'!$B:$AO,HLOOKUP(O$6,'BD_T.C.'!$6:$7,2,FALSE),FALSE) -> 5.7688207 | R108: =VLOOKUP($B108,'BD_T.C.'!$B:$AO,HLOOKUP(R$6,'BD_T.C.'!$6:$7,2,FALSE),FALSE) -> 955.422 | S108: =VLOOKUP("PROM-"&MONTH($B108)&YEAR($B108),'BD_T.C.'!$B:$AO,HLOOKUP(R$6,'BD_T.C.'!$6:$7,2,FALSE),FALSE) -> 957.6595 | U108: =VLOOKUP($B108,'BD_T.C.'!$B:$AO,HLOOKUP(U$6,'BD_T.C.'!$6:$7,2,FALSE),FALSE) -> 4138.17 | V108: =VLOOKUP("PROM-"&MONTH($B108)&YEAR($B108),'BD_T.C.'!$B:$AO,HLOOKUP(U$6,'BD_T.C.'!$6:$7,2,FALSE),FALSE) -> 4132.2496 | X108: =VLOOKUP($B108,'BD_T.C.'!$B:$AO,HLOOKUP(X$6,'BD_T.C.'!$6:$7,2,FALSE),FALSE) -> 7923.17 | Y108: =VLOOKUP("PROM-"&MONTH($B108)&YEAR($B108),'BD_T.C.'!$B:$AO,HLOOKUP(X$6,'BD_T.C.'!$6:$7,2,FALSE),FALSE) -> 7888.8043 | AA108: =VLOOKUP($B108,'BD_T.C.'!$B:$AO,HLOOKUP(AA$6,'BD_T.C.'!$6:$7,2,FALSE),FALSE) -> 1351.32 | AB108: =VLOOKUP("PROM-"&MONTH($B108)&YEAR($B108),'BD_T.C.'!$B:$AO,HLOOKUP(AA$6,'BD_T.C.'!$6:$7,2,FALSE),FALSE) -> 1367.58 | AD108: =VLOOKUP($B108,'BD_T.C.'!$B:$AO,HLOOKUP(AD$6,'BD_T.C.'!$6:$7,2,FALSE),FALSE) -> 3.68721 | AE108: =VLOOKUP("PROM-"&MONTH($B108)&YEAR($B108),'BD_T.C.'!$B:$AO,HLOOKUP(AD$6,'BD_T.C.'!$6:$7,2,FALSE),FALSE) -> 3.7031929 | AG108: =VLOOKUP($B108,'BD_T.C.'!$B:$AO,HLOOKUP(AG$6,'BD_T.C.'!$6:$7,2,FALSE),FALSE) -> 42.7954 | AH108: =VLOOKUP("PROM-"&MONTH($B108)&YEAR($B108),'BD_T.C.'!$B:$AO,HLOOKUP(AG$6,'BD_T.C.'!$6:$7,2,FALSE),FALSE) -> 43.267546 | AJ108: =VLOOKUP($B108,'BD_T.C.'!$B:$AO,HLOOKUP(AJ$6,'BD_T.C.'!$6:$7,2,FALSE),FALSE) -> 7.29888 | AK108: =VLOOKUP("PROM-"&MONTH($B108)&YEAR($B108),'BD_T.C.'!$B:$AO,HLOOKUP(AJ$6,'BD_T.C.'!$6:$7,2,FALSE),FALSE) -> 7.5007854 | AM108: =VLOOKUP($B108,'BD_T.C.'!$B:$AO,HLOOKUP(AM$6,'BD_T.C.'!$6:$7,2,FALSE),FALSE) -> 507.299 | AN108: =VLOOKUP("PROM-"&MONTH($B108)&YEAR($B108),'BD_T.C.'!$B:$AO,HLOOKUP(AM$6,'BD_T.C.'!$6:$7,2,FALSE),FALSE) -> 507.11189 | AP108: =VLOOKUP($B108,'BD_T.C.'!$B:$AO,HLOOKUP(AP$6,'BD_T.C.'!$6:$7,2,FALSE),FALSE) -> 62.5662 | AQ108: =VLOOKUP("PROM-"&MONTH($B108)&YEAR($B108),'BD_T.C.'!$B:$AO,HLOOKUP(AP$6,'BD_T.C.'!$6:$7,2,FALSE),FALSE) -> 62.172864 | AS108: =VLOOKUP($B108,'BD_T.C.'!$B:$AO,HLOOKUP(AS$6,'BD_T.C.'!$6:$7,2,FALSE),FALSE) -> 1 | AT108: =VLOOKUP("PROM-"&MONTH($B108)&YEAR($B108),'BD_T.C.'!$B:$AO,HLOOKUP(AS$6,'BD_T.C.'!$6:$7,2,FALSE),FALSE) -> 1 | AV108: =VLOOKUP($B108,'BD_T.C.'!$B:$AO,HLOOKUP(AV$6,'BD_T.C.'!$6:$7,2,FALSE),FALSE) -> 7.72824 | AW108: =VLOOKUP("PROM-"&MONTH($B108)&YEAR($B108),'BD_T.C.'!$B:$AO,HLOOKUP(AV$6,'BD_T.C.'!$6:$7,2,FALSE),FALSE) -> 7.7263875 | AY108: =VLOOKUP($B108,'BD_T.C.'!$B:$AO,HLOOKUP(AY$6,'BD_T.C.'!$6:$7,2,FALSE),FALSE) -> 8.75 | AZ108: =VLOOKUP("PROM-"&MONTH($B108)&YEAR($B108),'BD_T.C.'!$B:$AO,HLOOKUP(AY$6,'BD_T.C.'!$6:$7,2,FALSE),FALSE) -> 8.75 | BB108: =VLOOKUP($B108,'BD_T.C.'!$B:$AO,HLOOKUP(BB$6,'BD_T.C.'!$6:$7,2,FALSE),FALSE) -> 25.6712 | BC108: =VLOOKUP("PROM-"&MONTH($B108)&YEAR($B108),'BD_T.C.'!$B:$AO,HLOOKUP(BB$6,'BD_T.C.'!$6:$7,2,FALSE),FALSE) -> 25.577171 | BE108: =VLOOKUP($B108,'BD_T.C.'!$B:$AO,HLOOKUP(BE$6,'BD_T.C.'!$6:$7,2,FALSE),FALSE) -> 36.866 | BF108: =VLOOKUP("PROM-"&MONTH($B108)&YEAR($B108),'BD_T.C.'!$B:$AO,HLOOKUP(BE$6,'BD_T.C.'!$6:$7,2,FALSE),FALSE) -> 36.786761 | BH108: =VLOOKUP($B108,'BD_T.C.'!$B:$AO,HLOOKUP(BH$6,'BD_T.C.'!$6:$7,2,FALSE),FALSE) -> 6.796 | BI108: =VLOOKUP("PROM-"&MONTH($B108)&YEAR($B108),'BD_T.C.'!$B:$AO,HLOOKUP(BH$6,'BD_T.C.'!$6:$7,2,FALSE),FALSE) -> 6.7855543
B109: 45747 | C109: =VLOOKUP($B109,'BD_T.C.'!$B:$AO,HLOOKUP(C$6,'BD_T.C.'!$6:$7,2,FALSE),FALSE) -> 20.4003 | D109: =VLOOKUP("PROM-"&MONTH($B109)&YEAR($B109),'BD_T.C.'!$B:$AO,HLOOKUP(C$6,'BD_T.C.'!$6:$7,2,FALSE),FALSE) -> 20.244016 | F109: =VLOOKUP($B109,'BD_T.C.'!$B:$AO,HLOOKUP(F$6,'BD_T.C.'!$6:$7,2,FALSE),FALSE) -> 0.924114 | G109: =VLOOKUP("PROM-"&MONTH($B109)&YEAR($B109),'BD_T.C.'!$B:$AO,HLOOKUP(F$6,'BD_T.C.'!$6:$7,2,FALSE),FALSE) -> 0.92718639 | I109: =VLOOKUP($B109,'BD_T.C.'!$B:$AO,HLOOKUP(I$6,'BD_T.C.'!$6:$7,2,FALSE),FALSE) -> 1070.5 | J109: =VLOOKUP("PROM-"&MONTH($B109)&YEAR($B109),'BD_T.C.'!$B:$AO,HLOOKUP(I$6,'BD_T.C.'!$6:$7,2,FALSE),FALSE) -> 1067.041 | L109: =VLOOKUP($B109,'BD_T.C.'!$B:$AO,HLOOKUP(L$6,'BD_T.C.'!$6:$7,2,FALSE),FALSE) -> 6.91684 | M109: =VLOOKUP("PROM-"&MONTH($B109)&YEAR($B109),'BD_T.C.'!$B:$AO,HLOOKUP(L$6,'BD_T.C.'!$6:$7,2,FALSE),FALSE) -> 6.911429 | O109: =VLOOKUP($B109,'BD_T.C.'!$B:$AO,HLOOKUP(O$6,'BD_T.C.'!$6:$7,2,FALSE),FALSE) -> 5.7454 | P109: =VLOOKUP("PROM-"&MONTH($B109)&YEAR($B109),'BD_T.C.'!$B:$AO,HLOOKUP(O$6,'BD_T.C.'!$6:$7,2,FALSE),FALSE) -> 5.7804687 | R109: =VLOOKUP($B109,'BD_T.C.'!$B:$AO,HLOOKUP(R$6,'BD_T.C.'!$6:$7,2,FALSE),FALSE) -> 945.086 | S109: =VLOOKUP("PROM-"&MONTH($B109)&YEAR($B109),'BD_T.C.'!$B:$AO,HLOOKUP(R$6,'BD_T.C.'!$6:$7,2,FALSE),FALSE) -> 935.36471 | U109: =VLOOKUP($B109,'BD_T.C.'!$B:$AO,HLOOKUP(U$6,'BD_T.C.'!$6:$7,2,FALSE),FALSE) -> 4173.61 | V109: =VLOOKUP("PROM-"&MONTH($B109)&YEAR($B109),'BD_T.C.'!$B:$AO,HLOOKUP(U$6,'BD_T.C.'!$6:$7,2,FALSE),FALSE) -> 4139.6487 | X109: =VLOOKUP($B109,'BD_T.C.'!$B:$AO,HLOOKUP(X$6,'BD_T.C.'!$6:$7,2,FALSE),FALSE) -> 7970.52 | Y109: =VLOOKUP("PROM-"&MONTH($B109)&YEAR($B109),'BD_T.C.'!$B:$AO,HLOOKUP(X$6,'BD_T.C.'!$6:$7,2,FALSE),FALSE) -> 7948.6681 | AA109: =VLOOKUP($B109,'BD_T.C.'!$B:$AO,HLOOKUP(AA$6,'BD_T.C.'!$6:$7,2,FALSE),FALSE) -> 1387.29 | AB109: =VLOOKUP("PROM-"&MONTH($B109)&YEAR($B109),'BD_T.C.'!$B:$AO,HLOOKUP(AA$6,'BD_T.C.'!$6:$7,2,FALSE),FALSE) -> 1375.4765 | AD109: =VLOOKUP($B109,'BD_T.C.'!$B:$AO,HLOOKUP(AD$6,'BD_T.C.'!$6:$7,2,FALSE),FALSE) -> 3.64984 | AE109: =VLOOKUP("PROM-"&MONTH($B109)&YEAR($B109),'BD_T.C.'!$B:$AO,HLOOKUP(AD$6,'BD_T.C.'!$6:$7,2,FALSE),FALSE) -> 3.6557952 | AG109: =VLOOKUP($B109,'BD_T.C.'!$B:$AO,HLOOKUP(AG$6,'BD_T.C.'!$6:$7,2,FALSE),FALSE) -> 42.11 | AH109: =VLOOKUP("PROM-"&MONTH($B109)&YEAR($B109),'BD_T.C.'!$B:$AO,HLOOKUP(AG$6,'BD_T.C.'!$6:$7,2,FALSE),FALSE) -> 42.411642 | AJ109: =VLOOKUP($B109,'BD_T.C.'!$B:$AO,HLOOKUP(AJ$6,'BD_T.C.'!$6:$7,2,FALSE),FALSE) -> 7.32937 | AK109: =VLOOKUP("PROM-"&MONTH($B109)&YEAR($B109),'BD_T.C.'!$B:$AO,HLOOKUP(AJ$6,'BD_T.C.'!$6:$7,2,FALSE),FALSE) -> 7.3386006 | AM109: =VLOOKUP($B109,'BD_T.C.'!$B:$AO,HLOOKUP(AM$6,'BD_T.C.'!$6:$7,2,FALSE),FALSE) -> 498.994 | AN109: =VLOOKUP("PROM-"&MONTH($B109)&YEAR($B109),'BD_T.C.'!$B:$AO,HLOOKUP(AM$6,'BD_T.C.'!$6:$7,2,FALSE),FALSE) -> 501.62568 | AP109: =VLOOKUP($B109,'BD_T.C.'!$B:$AO,HLOOKUP(AP$6,'BD_T.C.'!$6:$7,2,FALSE),FALSE) -> 63.0088 | AQ109: =VLOOKUP("PROM-"&MONTH($B109)&YEAR($B109),'BD_T.C.'!$B:$AO,HLOOKUP(AP$6,'BD_T.C.'!$6:$7,2,FALSE),FALSE) -> 62.773345 | AS109: =VLOOKUP($B109,'BD_T.C.'!$B:$AO,HLOOKUP(AS$6,'BD_T.C.'!$6:$7,2,FALSE),FALSE) -> 1 | AT109: =VLOOKUP("PROM-"&MONTH($B109)&YEAR($B109),'BD_T.C.'!$B:$AO,HLOOKUP(AS$6,'BD_T.C.'!$6:$7,2,FALSE),FALSE) -> 1 | AV109: =VLOOKUP($B109,'BD_T.C.'!$B:$AO,HLOOKUP(AV$6,'BD_T.C.'!$6:$7,2,FALSE),FALSE) -> 7.7076 | AW109: =VLOOKUP("PROM-"&MONTH($B109)&YEAR($B109),'BD_T.C.'!$B:$AO,HLOOKUP(AV$6,'BD_T.C.'!$6:$7,2,FALSE),FALSE) -> 7.7087755 | AY109: =VLOOKUP($B109,'BD_T.C.'!$B:$AO,HLOOKUP(AY$6,'BD_T.C.'!$6:$7,2,FALSE),FALSE) -> 8.75 | AZ109: =VLOOKUP("PROM-"&MONTH($B109)&YEAR($B109),'BD_T.C.'!$B:$AO,HLOOKUP(AY$6,'BD_T.C.'!$6:$7,2,FALSE),FALSE) -> 8.75 | BB109: =VLOOKUP($B109,'BD_T.C.'!$B:$AO,HLOOKUP(BB$6,'BD_T.C.'!$6:$7,2,FALSE),FALSE) -> 25.5428 | BC109: =VLOOKUP("PROM-"&MONTH($B109)&YEAR($B109),'BD_T.C.'!$B:$AO,HLOOKUP(BB$6,'BD_T.C.'!$6:$7,2,FALSE),FALSE) -> 25.61829 | BE109: =VLOOKUP($B109,'BD_T.C.'!$B:$AO,HLOOKUP(BE$6,'BD_T.C.'!$6:$7,2,FALSE),FALSE) -> 36.696 | BF109: =VLOOKUP("PROM-"&MONTH($B109)&YEAR($B109),'BD_T.C.'!$B:$AO,HLOOKUP(BE$6,'BD_T.C.'!$6:$7,2,FALSE),FALSE) -> 36.780823 | BH109: =VLOOKUP($B109,'BD_T.C.'!$B:$AO,HLOOKUP(BH$6,'BD_T.C.'!$6:$7,2,FALSE),FALSE) -> 6.78074 | BI109: =VLOOKUP("PROM-"&MONTH($B109)&YEAR($B109),'BD_T.C.'!$B:$AO,HLOOKUP(BH$6,'BD_T.C.'!$6:$7,2,FALSE),FALSE) -> 6.7868729
B110: 45777 | C110: =VLOOKUP($B110,'BD_T.C.'!$B:$AO,HLOOKUP(C$6,'BD_T.C.'!$6:$7,2,FALSE),FALSE) -> 19.5868 | D110: =VLOOKUP("PROM-"&MONTH($B110)&YEAR($B110),'BD_T.C.'!$B:$AO,HLOOKUP(C$6,'BD_T.C.'!$6:$7,2,FALSE),FALSE) -> 20.071047 | F110: =VLOOKUP($B110,'BD_T.C.'!$B:$AO,HLOOKUP(F$6,'BD_T.C.'!$6:$7,2,FALSE),FALSE) -> 0.880206 | G110: =VLOOKUP("PROM-"&MONTH($B110)&YEAR($B110),'BD_T.C.'!$B:$AO,HLOOKUP(F$6,'BD_T.C.'!$6:$7,2,FALSE),FALSE) -> 0.89007347 | I110: =VLOOKUP($B110,'BD_T.C.'!$B:$AO,HLOOKUP(I$6,'BD_T.C.'!$6:$7,2,FALSE),FALSE) -> 1167.59 | J110: =VLOOKUP("PROM-"&MONTH($B110)&YEAR($B110),'BD_T.C.'!$B:$AO,HLOOKUP(I$6,'BD_T.C.'!$6:$7,2,FALSE),FALSE) -> 1111.6273 | L110: =VLOOKUP($B110,'BD_T.C.'!$B:$AO,HLOOKUP(L$6,'BD_T.C.'!$6:$7,2,FALSE),FALSE) -> 6.90816 | M110: =VLOOKUP("PROM-"&MONTH($B110)&YEAR($B110),'BD_T.C.'!$B:$AO,HLOOKUP(L$6,'BD_T.C.'!$6:$7,2,FALSE),FALSE) -> 6.906265 | O110: =VLOOKUP($B110,'BD_T.C.'!$B:$AO,HLOOKUP(O$6,'BD_T.C.'!$6:$7,2,FALSE),FALSE) -> 5.64442 | P110: =VLOOKUP("PROM-"&MONTH($B110)&YEAR($B110),'BD_T.C.'!$B:$AO,HLOOKUP(O$6,'BD_T.C.'!$6:$7,2,FALSE),FALSE) -> 5.7874387 | R110: =VLOOKUP($B110,'BD_T.C.'!$B:$AO,HLOOKUP(R$6,'BD_T.C.'!$6:$7,2,FALSE),FALSE) -> 948.906 | S110: =VLOOKUP("PROM-"&MONTH($B110)&YEAR($B110),'BD_T.C.'!$B:$AO,HLOOKUP(R$6,'BD_T.C.'!$6:$7,2,FALSE),FALSE) -> 961.4885 | U110: =VLOOKUP($B110,'BD_T.C.'!$B:$AO,HLOOKUP(U$6,'BD_T.C.'!$6:$7,2,FALSE),FALSE) -> 4211.54 | V110: =VLOOKUP("PROM-"&MONTH($B110)&YEAR($B110),'BD_T.C.'!$B:$AO,HLOOKUP(U$6,'BD_T.C.'!$6:$7,2,FALSE),FALSE) -> 4271.4947 | X110: =VLOOKUP($B110,'BD_T.C.'!$B:$AO,HLOOKUP(X$6,'BD_T.C.'!$6:$7,2,FALSE),FALSE) -> 8003.22 | Y110: =VLOOKUP("PROM-"&MONTH($B110)&YEAR($B110),'BD_T.C.'!$B:$AO,HLOOKUP(X$6,'BD_T.C.'!$6:$7,2,FALSE),FALSE) -> 7998.5657 | AA110: =VLOOKUP($B110,'BD_T.C.'!$B:$AO,HLOOKUP(AA$6,'BD_T.C.'!$6:$7,2,FALSE),FALSE) -> 1417.9 | AB110: =VLOOKUP("PROM-"&MONTH($B110)&YEAR($B110),'BD_T.C.'!$B:$AO,HLOOKUP(AA$6,'BD_T.C.'!$6:$7,2,FALSE),FALSE) -> 1382.4357 | AD110: =VLOOKUP($B110,'BD_T.C.'!$B:$AO,HLOOKUP(AD$6,'BD_T.C.'!$6:$7,2,FALSE),FALSE) -> 3.6658 | AE110: =VLOOKUP("PROM-"&MONTH($B110)&YEAR($B110),'BD_T.C.'!$B:$AO,HLOOKUP(AD$6,'BD_T.C.'!$6:$7,2,FALSE),FALSE) -> 3.701932 | AG110: =VLOOKUP($B110,'BD_T.C.'!$B:$AO,HLOOKUP(AG$6,'BD_T.C.'!$6:$7,2,FALSE),FALSE) -> 42.0586 | AH110: =VLOOKUP("PROM-"&MONTH($B110)&YEAR($B110),'BD_T.C.'!$B:$AO,HLOOKUP(AG$6,'BD_T.C.'!$6:$7,2,FALSE),FALSE) -> 42.27361 | AJ110: =VLOOKUP($B110,'BD_T.C.'!$B:$AO,HLOOKUP(AJ$6,'BD_T.C.'!$6:$7,2,FALSE),FALSE) -> 7.4514 | AK110: =VLOOKUP("PROM-"&MONTH($B110)&YEAR($B110),'BD_T.C.'!$B:$AO,HLOOKUP(AJ$6,'BD_T.C.'!$6:$7,2,FALSE),FALSE) -> 7.30584 | AM110: =VLOOKUP($B110,'BD_T.C.'!$B:$AO,HLOOKUP(AM$6,'BD_T.C.'!$6:$7,2,FALSE),FALSE) -> 505.276 | AN110: =VLOOKUP("PROM-"&MONTH($B110)&YEAR($B110),'BD_T.C.'!$B:$AO,HLOOKUP(AM$6,'BD_T.C.'!$6:$7,2,FALSE),FALSE) -> 505.8989 | AP110: =VLOOKUP($B110,'BD_T.C.'!$B:$AO,HLOOKUP(AP$6,'BD_T.C.'!$6:$7,2,FALSE),FALSE) -> 58.8596 | AQ110: =VLOOKUP("PROM-"&MONTH($B110)&YEAR($B110),'BD_T.C.'!$B:$AO,HLOOKUP(AP$6,'BD_T.C.'!$6:$7,2,FALSE),FALSE) -> 60.993817 | AS110: =VLOOKUP($B110,'BD_T.C.'!$B:$AO,HLOOKUP(AS$6,'BD_T.C.'!$6:$7,2,FALSE),FALSE) -> 1 | AT110: =VLOOKUP("PROM-"&MONTH($B110)&YEAR($B110),'BD_T.C.'!$B:$AO,HLOOKUP(AS$6,'BD_T.C.'!$6:$7,2,FALSE),FALSE) -> 1 | AV110: =VLOOKUP($B110,'BD_T.C.'!$B:$AO,HLOOKUP(AV$6,'BD_T.C.'!$6:$7,2,FALSE),FALSE) -> 7.69984 | AW110: =VLOOKUP("PROM-"&MONTH($B110)&YEAR($B110),'BD_T.C.'!$B:$AO,HLOOKUP(AV$6,'BD_T.C.'!$6:$7,2,FALSE),FALSE) -> 7.7050553 | AY110: =VLOOKUP($B110,'BD_T.C.'!$B:$AO,HLOOKUP(AY$6,'BD_T.C.'!$6:$7,2,FALSE),FALSE) -> 8.75 | AZ110: =VLOOKUP("PROM-"&MONTH($B110)&YEAR($B110),'BD_T.C.'!$B:$AO,HLOOKUP(AY$6,'BD_T.C.'!$6:$7,2,FALSE),FALSE) -> 8.75 | BB110: =VLOOKUP($B110,'BD_T.C.'!$B:$AO,HLOOKUP(BB$6,'BD_T.C.'!$6:$7,2,FALSE),FALSE) -> 25.8896 | BC110: =VLOOKUP("PROM-"&MONTH($B110)&YEAR($B110),'BD_T.C.'!$B:$AO,HLOOKUP(BB$6,'BD_T.C.'!$6:$7,2,FALSE),FALSE) -> 25.792207 | BE110: =VLOOKUP($B110,'BD_T.C.'!$B:$AO,HLOOKUP(BE$6,'BD_T.C.'!$6:$7,2,FALSE),FALSE) -> 36.7656 | BF110: =VLOOKUP("PROM-"&MONTH($B110)&YEAR($B110),'BD_T.C.'!$B:$AO,HLOOKUP(BE$6,'BD_T.C.'!$6:$7,2,FALSE),FALSE) -> 36.778967 | BH110: =VLOOKUP($B110,'BD_T.C.'!$B:$AO,HLOOKUP(BH$6,'BD_T.C.'!$6:$7,2,FALSE),FALSE) -> 6.77297 | BI110: =VLOOKUP("PROM-"&MONTH($B110)&YEAR($B110),'BD_T.C.'!$B:$AO,HLOOKUP(BH$6,'BD_T.C.'!$6:$7,2,FALSE),FALSE) -> 6.7826927
B111: 45808 | C111: =VLOOKUP($B111,'BD_T.C.'!$B:$AO,HLOOKUP(C$6,'BD_T.C.'!$6:$7,2,FALSE),FALSE) -> 19.328 | D111: =VLOOKUP("PROM-"&MONTH($B111)&YEAR($B111),'BD_T.C.'!$B:$AO,HLOOKUP(C$6,'BD_T.C.'!$6:$7,2,FALSE),FALSE) -> 19.459119 | F111: =VLOOKUP($B111,'BD_T.C.'!$B:$AO,HLOOKUP(F$6,'BD_T.C.'!$6:$7,2,FALSE),FALSE) -> 0.881224 | G111: =VLOOKUP("PROM-"&MONTH($B111)&YEAR($B111),'BD_T.C.'!$B:$AO,HLOOKUP(F$6,'BD_T.C.'!$6:$7,2,FALSE),FALSE) -> 0.88655561 | I111: =VLOOKUP($B111,'BD_T.C.'!$B:$AO,HLOOKUP(I$6,'BD_T.C.'!$6:$7,2,FALSE),FALSE) -> 1189.26 | J111: =VLOOKUP("PROM-"&MONTH($B111)&YEAR($B111),'BD_T.C.'!$B:$AO,HLOOKUP(I$6,'BD_T.C.'!$6:$7,2,FALSE),FALSE) -> 1149.9084 | L111: =VLOOKUP($B111,'BD_T.C.'!$B:$AO,HLOOKUP(L$6,'BD_T.C.'!$6:$7,2,FALSE),FALSE) -> 6.90524 | M111: =VLOOKUP("PROM-"&MONTH($B111)&YEAR($B111),'BD_T.C.'!$B:$AO,HLOOKUP(L$6,'BD_T.C.'!$6:$7,2,FALSE),FALSE) -> 6.91352 | O111: =VLOOKUP($B111,'BD_T.C.'!$B:$AO,HLOOKUP(O$6,'BD_T.C.'!$6:$7,2,FALSE),FALSE) -> 5.72362 | P111: =VLOOKUP("PROM-"&MONTH($B111)&YEAR($B111),'BD_T.C.'!$B:$AO,HLOOKUP(O$6,'BD_T.C.'!$6:$7,2,FALSE),FALSE) -> 5.6685568 | R111: =VLOOKUP($B111,'BD_T.C.'!$B:$AO,HLOOKUP(R$6,'BD_T.C.'!$6:$7,2,FALSE),FALSE) -> 944.362 | S111: =VLOOKUP("PROM-"&MONTH($B111)&YEAR($B111),'BD_T.C.'!$B:$AO,HLOOKUP(R$6,'BD_T.C.'!$6:$7,2,FALSE),FALSE) -> 941.71729 | U111: =VLOOKUP($B111,'BD_T.C.'!$B:$AO,HLOOKUP(U$6,'BD_T.C.'!$6:$7,2,FALSE),FALSE) -> 4154.98 | V111: =VLOOKUP("PROM-"&MONTH($B111)&YEAR($B111),'BD_T.C.'!$B:$AO,HLOOKUP(U$6,'BD_T.C.'!$6:$7,2,FALSE),FALSE) -> 4202.2481 | X111: =VLOOKUP($B111,'BD_T.C.'!$B:$AO,HLOOKUP(X$6,'BD_T.C.'!$6:$7,2,FALSE),FALSE) -> 7983.66 | Y111: =VLOOKUP("PROM-"&MONTH($B111)&YEAR($B111),'BD_T.C.'!$B:$AO,HLOOKUP(X$6,'BD_T.C.'!$6:$7,2,FALSE),FALSE) -> 7989.7684 | AA111: =VLOOKUP($B111,'BD_T.C.'!$B:$AO,HLOOKUP(AA$6,'BD_T.C.'!$6:$7,2,FALSE),FALSE) -> 1394.86 | AB111: =VLOOKUP("PROM-"&MONTH($B111)&YEAR($B111),'BD_T.C.'!$B:$AO,HLOOKUP(AA$6,'BD_T.C.'!$6:$7,2,FALSE),FALSE) -> 1409.5145 | AD111: =VLOOKUP($B111,'BD_T.C.'!$B:$AO,HLOOKUP(AD$6,'BD_T.C.'!$6:$7,2,FALSE),FALSE) -> 3.61968 | AE111: =VLOOKUP("PROM-"&MONTH($B111)&YEAR($B111),'BD_T.C.'!$B:$AO,HLOOKUP(AD$6,'BD_T.C.'!$6:$7,2,FALSE),FALSE) -> 3.6612171 | AG111: =VLOOKUP($B111,'BD_T.C.'!$B:$AO,HLOOKUP(AG$6,'BD_T.C.'!$6:$7,2,FALSE),FALSE) -> 41.6023 | AH111: =VLOOKUP("PROM-"&MONTH($B111)&YEAR($B111),'BD_T.C.'!$B:$AO,HLOOKUP(AG$6,'BD_T.C.'!$6:$7,2,FALSE),FALSE) -> 41.761645 | AJ111: =VLOOKUP($B111,'BD_T.C.'!$B:$AO,HLOOKUP(AJ$6,'BD_T.C.'!$6:$7,2,FALSE),FALSE) -> 7.26854 | AK111: =VLOOKUP("PROM-"&MONTH($B111)&YEAR($B111),'BD_T.C.'!$B:$AO,HLOOKUP(AJ$6,'BD_T.C.'!$6:$7,2,FALSE),FALSE) -> 7.3673768 | AM111: =VLOOKUP($B111,'BD_T.C.'!$B:$AO,HLOOKUP(AM$6,'BD_T.C.'!$6:$7,2,FALSE),FALSE) -> 507.719 | AN111: =VLOOKUP("PROM-"&MONTH($B111)&YEAR($B111),'BD_T.C.'!$B:$AO,HLOOKUP(AM$6,'BD_T.C.'!$6:$7,2,FALSE),FALSE) -> 507.17945 | AP111: =VLOOKUP($B111,'BD_T.C.'!$B:$AO,HLOOKUP(AP$6,'BD_T.C.'!$6:$7,2,FALSE),FALSE) -> 58.9848 | AQ111: =VLOOKUP("PROM-"&MONTH($B111)&YEAR($B111),'BD_T.C.'!$B:$AO,HLOOKUP(AP$6,'BD_T.C.'!$6:$7,2,FALSE),FALSE) -> 58.896519 | AS111: =VLOOKUP($B111,'BD_T.C.'!$B:$AO,HLOOKUP(AS$6,'BD_T.C.'!$6:$7,2,FALSE),FALSE) -> 1 | AT111: =VLOOKUP("PROM-"&MONTH($B111)&YEAR($B111),'BD_T.C.'!$B:$AO,HLOOKUP(AS$6,'BD_T.C.'!$6:$7,2,FALSE),FALSE) -> 1 | AV111: =VLOOKUP($B111,'BD_T.C.'!$B:$AO,HLOOKUP(AV$6,'BD_T.C.'!$6:$7,2,FALSE),FALSE) -> 7.67728 | AW111: =VLOOKUP("PROM-"&MONTH($B111)&YEAR($B111),'BD_T.C.'!$B:$AO,HLOOKUP(AV$6,'BD_T.C.'!$6:$7,2,FALSE),FALSE) -> 7.6850113 | AY111: =VLOOKUP($B111,'BD_T.C.'!$B:$AO,HLOOKUP(AY$6,'BD_T.C.'!$6:$7,2,FALSE),FALSE) -> 8.75 | AZ111: =VLOOKUP("PROM-"&MONTH($B111)&YEAR($B111),'BD_T.C.'!$B:$AO,HLOOKUP(AY$6,'BD_T.C.'!$6:$7,2,FALSE),FALSE) -> 8.75 | BB111: =VLOOKUP($B111,'BD_T.C.'!$B:$AO,HLOOKUP(BB$6,'BD_T.C.'!$6:$7,2,FALSE),FALSE) -> 26.0239 | BC111: =VLOOKUP("PROM-"&MONTH($B111)&YEAR($B111),'BD_T.C.'!$B:$AO,HLOOKUP(BB$6,'BD_T.C.'!$6:$7,2,FALSE),FALSE) -> 25.967965 | BE111: =VLOOKUP($B111,'BD_T.C.'!$B:$AO,HLOOKUP(BE$6,'BD_T.C.'!$6:$7,2,FALSE),FALSE) -> 36.794 | BF111: =VLOOKUP("PROM-"&MONTH($B111)&YEAR($B111),'BD_T.C.'!$B:$AO,HLOOKUP(BE$6,'BD_T.C.'!$6:$7,2,FALSE),FALSE) -> 36.777248 | BH111: =VLOOKUP($B111,'BD_T.C.'!$B:$AO,HLOOKUP(BH$6,'BD_T.C.'!$6:$7,2,FALSE),FALSE) -> 6.78868 | BI111: =VLOOKUP("PROM-"&MONTH($B111)&YEAR($B111),'BD_T.C.'!$B:$AO,HLOOKUP(BH$6,'BD_T.C.'!$6:$7,2,FALSE),FALSE) -> 6.7879232
...

Sheet BD_T.C.
B1: Genomma Lab Internacional
B2: TIPOS DE CAMBIO DE MODENA LOCAL POR PAÍS A DÓLAR ESTADOUNIDENSE
B3: =Resumen!B4 -> Para el cierre de Marzo de 2026
C5: USD / MXN | E5: USD / EUR | G5: USD / ARS | I5: USD / BOB | K5: USD / BRL | M5: USD / CLP | O5: USD / COP | Q5: USD / PYG | S5: BRL / PYG | U5: USD / PEN | W5: USD / UYU | Y5: BRL / UYU | AA5: USD / CRC | AC5: USD / DOP | AE5: USD / PAB | AG5: USD / GTQ | AI5: USD / SVC | AK5: USD / HNL | AM5: USD / NIO | AO5: USD / TTD
B6: Fecha | C6: MÉXICO | E6: ESPAÑA | G6: ARGENTINA | I6: BOLIVIA | K6: BRASIL | M6: CHILE | O6: COLOMBIA | Q6: PARAGUAY | S6: PARAGUAY [REAL] | U6: PERÚ | W6: URUGUAY | Y6: URUGUAY [REAL] | AA6: COSTA RICA | AC6: DOMINICANA | AE6: PANAMÁ | AG6: GUATEMALA | AI6: EL SALVADOR | AK6: HONDURAS | AM6: NICARAGUA | AO6: TRINIDAD Y TOBAGO
C7: =COLUMN()-1 -> 2 | E7: =COLUMN()-1 -> 4 | G7: =COLUMN()-1 -> 6 | I7: =COLUMN()-1 -> 8 | K7: =COLUMN()-1 -> 10 | M7: =COLUMN()-1 -> 12 | O7: =COLUMN()-1 -> 14 | Q7: =COLUMN()-1 -> 16 | S7: =COLUMN()-1 -> 18 | U7: =COLUMN()-1 -> 20 | W7: =COLUMN()-1 -> 22 | Y7: =COLUMN()-1 -> 24 | AA7: =COLUMN()-1 -> 26 | AC7: =COLUMN()-1 -> 28 | AE7: =COLUMN()-1 -> 30 | AG7: =COLUMN()-1 -> 32 | AI7: =COLUMN()-1 -> 34 | AK7: =COLUMN()-1 -> 36 | AM7: =COLUMN()-1 -> 38 | AO7: =COLUMN()-1 -> 40
B8: 42370 | C8: 17.2152 | E8: 0.92 | G8: 12.9725 | I8: 6.9307 | K8: 3.9597 | O8: 3183.75 | Q8: 5818.78 | S8: 1469.55 | U8: 3.4148 | W8: 30.0041 | Y8: 7.5776 | AA8: 540.013 | AC8: 45.6456 | AE8: 1 | AG8: 7.6548 | AI8: 8.8015 | AK8: 22.1963 | AM8: 27.8377
B9: 42371 | C9: 17.2152 | E9: 0.92 | G9: 12.9835 | I9: 6.9297 | K9: 3.9592 | O9: 3183.35 | Q9: 5818 | S9: 1469.54 | U9: 3.4144 | W9: 30 | Y9: 7.57753 | AA9: 539.94 | AC9: 45.6395 | AE9: 1 | AG9: 7.6538 | AI9: 8.8003 | AK9: 22.1935 | AM9: 27.8335
B10: 42372 | C10: 17.2152 | E10: 0.92 | G10: 12.9833 | I10: 6.9 | K10: 3.962 | O10: 3174.5 | Q10: 5730 | S10: 1446.24 | U10: 3.4025 | W10: 29.94 | Y10: 7.55679 | AA10: 539.8 | AC10: 45.13 | AE10: 1 | AG10: 7.633 | AI10: 8.7272 | AK10: 22.13 | AM10: 27.932
B11: 42373 | C11: 17.3157 | E11: 0.9203 | G11: 13.0251 | I11: 6.9249 | K11: 4.0026 | O11: 3195.18 | Q11: 5804.98 | S11: 1450.35 | U11: 3.4218 | W11: 29.9785 | Y11: 7.48998 | AA11: 539.545 | AC11: 45.6198 | AE11: 1 | AG11: 7.6566 | AI11: 8.7733 | AK11: 22.1771 | AM11: 27.8138
B12: 42374 | C12: 17.3165 | E12: 0.9271 | G12: 13.3208 | I12: 6.9357 | K12: 4.0283 | O12: 3206.98 | Q12: 5829.74 | S12: 1447.24 | U12: 3.4329 | W12: 30.1868 | Y12: 7.49394 | AA12: 540.117 | AC12: 45.7395 | AE12: 1 | AG12: 7.6841 | AI12: 8.7765 | AK12: 22.3295 | AM12: 27.8708
B13: 42375 | C13: 17.4182 | E13: 0.9302 | G13: 13.7043 | I13: 6.9056 | K13: 4.0252 | O13: 3231.18 | Q13: 5850.3 | S13: 1453.44 | U13: 3.4153 | W13: 30.2389 | Y13: 7.5125 | AA13: 537.028 | AC13: 45.5337 | AE13: 1 | AG13: 7.6566 | AI13: 8.7552 | AK13: 22.3773 | AM13: 27.7413
B14: 42376 | C14: 17.6289 | E14: 0.9231 | G14: 13.8669 | I14: 6.9009 | K14: 4.0371 | O14: 3244.05 | Q14: 5855.13 | S14: 1450.33 | U14: 3.4127 | W14: 30.1745 | Y14: 7.47426 | AA14: 536.168 | AC14: 45.4605 | AE14: 1 | AG14: 7.6468 | AI14: 8.7418 | AK14: 22.326 | AM14: 27.6749
B15: 42377 | C15: 17.8275 | E15: 0.9184 | G15: 13.8813 | I15: 6.8917 | K15: 4.0386 | O15: 3257.45 | Q15: 5849.43 | S15: 1448.43 | U15: 3.4053 | W15: 30.2538 | Y15: 7.49139 | AA15: 535.537 | AC15: 45.4146 | AE15: 1 | AG15: 7.6356 | AI15: 8.7271 | AK15: 22.3132 | AM15: 27.6279
B16: 42378 | C16: 17.9349 | E16: 0.9152 | G16: 13.8205 | I16: 6.877 | K16: 4.0261 | O16: 3255.25 | Q16: 5843.1 | S16: 1451.34 | U16: 3.4071 | W16: 30.309 | Y16: 7.52827 | AA16: 534.345 | AC16: 45.3125 | AE16: 1 | AG16: 7.6204 | AI16: 8.7084 | AK16: 22.2925 | AM16: 27.5625
B17: 42379 | C17: 17.9349 | E17: 0.9152 | G17: 13.8241 | I17: 6.877 | K17: 4.0262 | O17: 3255.25 | Q17: 5843.1 | S17: 1451.31 | U17: 3.4071 | W17: 30.309 | Y17: 7.52813 | AA17: 534.345 | AC17: 45.3125 | AE17: 1 | AG17: 7.6204 | AI17: 8.7084 | AK17: 22.2925 | AM17: 27.5625
B18: 42380 | C18: 17.9125 | E18: 0.9172 | G18: 13.8288 | I18: 6.8955 | K18: 4.0323 | O18: 3262.27 | Q18: 5860.34 | S18: 1453.4 | U18: 3.4162 | W18: 30.4001 | Y18: 7.53937 | AA18: 535.419 | AC18: 45.4426 | AE18: 1 | AG18: 7.6382 | AI18: 8.7316 | AK18: 22.3521 | AM18: 27.6184
B19: 42381 | C19: 17.8875 | E19: 0.9209 | G19: 13.6377 | I19: 6.9276 | K19: 4.0459 | O19: 3281.83 | Q19: 5892.02 | S19: 1456.34 | U19: 3.4335 | W19: 30.6075 | Y19: 7.56527 | AA19: 537.343 | AC19: 45.6724 | AE19: 1 | AG19: 7.669 | AI19: 8.7724 | AK19: 22.4665 | AM19: 27.7174
... B38: 42400 | C38: 18.2906 | E38: 0.9233 | G38: 13.9297 | I38: 6.9 | K38: 3.9983 | O38: 3282 | Q38: 5952 | S38: 1488.63 | U38: 3.4695 | W38: 31.08 | Y38: 7.7733 | AA38: 538.79 | AC38: 45.5 | AE38: 1 | AG38: 7.678 | AI38: 8.727 | AK38: 22.41 | AM38: 27.35
B39: PROM-12016 | C39: 18.017 | E39: 0.920406 | G39: 13.5426 | I39: 6.91124 | K39: 4.04229 | O39: 3278.26 | Q39: 5890.43 | S39: 1457.3 | U39: 3.43583 | W39: 30.63938 | Y39: 7.58005 | AA39: 536.716 | AC39: 45.5376 | AE39: 1 | AG39: 7.65021 | AI39: 8.75197 | AK39: 22.40045 | AM39: 27.63064
B40: 42401 | C40: 18.2095 | E40: 0.9207 | G40: 13.9787 | I40: 6.9336 | K40: 3.9918 | O40: 3303.45 | Q40: 5947.68 | S40: 1489.99 | U40: 3.4859 | W40: 31.1449 | Y40: 7.80228 | AA40: 539.736 | AC40: 45.7595 | AE40: 1 | AG40: 7.7002 | AI40: 8.7799 | AK40: 22.5234 | AM40: 27.4627
B41: 42402 | C41: 18.3581 | E41: 0.9168 | G41: 14.11 | I41: 6.8999 | K41: 3.9759 | O41: 3307.16 | Q41: 5912.31 | S41: 1487.06 | U41: 3.4826 | W41: 31.0098 | Y41: 7.79952 | AA41: 537.452 | AC41: 45.5133 | AE41: 1 | AG41: 7.6551 | AI41: 8.7368 | AK41: 22.3943 | AM41: 27.3157
B42: 42403 | C42: 18.4437 | E42: 0.9122 | G42: 14.118 | I42: 6.9095 | K42: 3.9637 | O42: 3349.21 | Q42: 5891.89 | S42: 1486.49 | U42: 3.4866 | W42: 31.0477 | Y42: 7.83319 | AA42: 538.3 | AC42: 45.6284 | AE42: 1 | AG42: 7.6585 | AI42: 8.7483 | AK42: 22.3971 | AM42: 27.308
B43: 42404 | C43: 18.175 | E43: 0.8976 | G43: 14.1578 | I43: 6.8419 | K43: 3.8867 | O43: 3345.92 | Q43: 5816.14 | S43: 1496.48 | U43: 3.4556 | W43: 30.7847 | Y43: 7.92084 | AA43: 533.229 | AC43: 45.2767 | AE43: 1 | AG43: 7.577 | AI43: 8.6638 | AK43: 22.2428 | AM43: 27.3506
B44: 42405 | C44: 18.2951 | E44: 0.8945 | G44: 14.2212 | I44: 6.8989 | K44: 3.8965 | O44: 3347.01 | Q44: 5873.81 | S44: 1507.5 | U44: 3.4794 | W44: 31.1008 | Y44: 7.98191 | AA44: 537.696 | AC44: 45.6855 | AE44: 1 | AG44: 7.6349 | AI44: 8.7372 | AK44: 22.5344 | AM44: 28.102
B45: 42406 | C45: 18.4467 | E45: 0.8962 | G45: 14.361 | I45: 6.9107 | K45: 3.9038 | O45: 3334 | Q45: 5886.45 | S45: 1507.94 | U45: 3.4805 | W45: 31.148 | Y45: 7.97921 | AA45: 538.595 | AC45: 45.715 | AE45: 1 | AG45: 7.6479 | AI45: 8.7516 | AK45: 22.55 | AM45: 28.05
B46: 42407 | C46: 18.446 | E46: 0.8962 | G46: 14.3623 | I46: 6.9107 | K46: 3.9038 | O46: 3334 | Q46: 5886.45 | S46: 1507.9 | U46: 3.4805 | W46: 31.148 | Y46: 7.97903 | AA46: 538.595 | AC46: 45.715 | AE46: 1 | AG46: 7.6479 | AI46: 8.7516 | AK46: 22.55 | AM46: 28.05
B47: 42408 | C47: 18.528 | E47: 0.897 | G47: 14.3423 | I47: 6.9255 | K47: 3.9001 | O47: 3345.49 | Q47: 5888.26 | S47: 1509.83 | U47: 3.4908 | W47: 31.2289 | Y47: 8.00748 | AA47: 539.69 | AC47: 45.8355 | AE47: 1 | AG47: 7.6646 | AI47: 8.7699 | AK47: 22.6175 | AM47: 28.2138
B48: 42409 | C48: 18.7419 | E48: 0.8903 | G48: 14.2834 | I48: 6.8782 | K48: 3.8937 | O48: 3370.06 | Q48: 5835.5 | S48: 1498.73 | U48: 3.4743 | W48: 31.0912 | Y48: 7.98515 | AA48: 535.28 | AC48: 45.6971 | AE48: 1 | AG48: 7.6124 | AI48: 8.7092 | AK48: 22.4647 | AM48: 27.9948
B49: 42410 | C49: 18.7861 | E49: 0.8874 | G49: 14.2809 | I49: 6.8839 | K49: 3.8992 | O49: 3363.04 | Q49: 5838.06 | S49: 1497.29 | U49: 3.4848 | W49: 31.1873 | Y49: 7.99857 | AA49: 535.348 | AC49: 45.5457 | AE49: 1 | AG49: 7.6212 | AI49: 8.717 | AK49: 22.4465 | AM49: 28.0036
B50: 42411 | C50: 19.0446 | E50: 0.884 | G50: 14.4688 | I50: 6.8909 | K50: 3.9491 | O50: 3393.1 | Q50: 5788.66 | S50: 1465.83 | U50: 3.4968 | W50: 31.2227 | Y50: 7.90632 | AA50: 536.194 | AC50: 45.5874 | AE50: 1 | AG50: 7.6327 | AI50: 8.726 | AK50: 22.4934 | AM50: 28.0286
B51: 42412 | C51: 19.0998 | E51: 0.8864 | G51: 14.6493 | I51: 6.9195 | K51: 3.9905 | O51: 3407.24 | Q51: 5770.48 | S51: 1446.09 | U51: 3.5135 | W51: 31.4137 | Y51: 7.87227 | AA51: 537.85 | AC51: 45.7295 | AE51: 1 | AG51: 7.6656 | AI51: 8.7616 | AK51: 22.6183 | AM51: 28.1211
... B68: 42429 | C68: 18.1706 | E68: 0.9168 | G68: 15.5828 | I68: 6.9007 | K68: 3.9912 | O68: 3332.06 | Q68: 5742.43 | S68: 1438.79 | U68: 3.5409 | W68: 32.2351 | Y68: 8.07664 | AA68: 538.156 | AC68: 45.6415 | AE68: 1 | AG68: 7.7144 | AI68: 8.7895 | AK68: 22.7104 | AM68: 28.2395
B69: PROM-22016 | C69: 18.4576 | E69: 0.900693 | G69: 14.7647 | I69: 6.89359 | K69: 3.96903 | O69: 3353.7 | Q69: 5808.8 | S69: 1463.82 | U69: 3.50313 | W69: 31.5838 | Y69: 7.95798 | AA69: 536.691 | AC69: 45.5564 | AE69: 1 | AG69: 7.66033 | AI69: 8.74549 | AK69: 22.5557 | AM69: 28.0156
B70: 42430 | C70: 18.043 | E70: 0.919739 | G70: 15.8346 | I70: 6.86476 | K70: 3.99546 | O70: 3315.41 | Q70: 5746.33 | S70: 1438.24 | U70: 3.52294 | W70: 32.1648 | Y70: 8.05048 | AA70: 536.255 | AC70: 45.4581 | AE70: 1 | AG70: 7.68893 | AI70: 8.75463 | AK70: 22.6455 | AM70: 28.1641
B71: 42431 | C71: 17.8849 | E71: 0.920874 | G71: 15.7454 | I71: 6.85323 | K71: 3.91535 | O71: 3261.98 | Q71: 5777.22 | S71: 1475.56 | U71: 3.51857 | W71: 32.2807 | Y71: 8.24481 | AA71: 536.231 | AC71: 45.4188 | AE71: 1 | AG71: 7.69046 | AI71: 8.75482 | AK71: 22.646 | AM71: 28.2233
B72: 42432 | C72: 17.8654 | E72: 0.918109 | G72: 15.5549 | I72: 6.84571 | K72: 3.86543 | O72: 3214.44 | Q72: 5729.77 | S72: 1482.35 | U72: 3.49842 | W72: 32.3813 | Y72: 8.3773 | AA72: 535.556 | AC72: 45.3674 | AE72: 1 | AG72: 7.67649 | AI72: 8.74366 | AK72: 22.5995 | AM72: 28.3365
B73: 42433 | C73: 17.8843 | E73: 0.911748 | G73: 15.2078 | I73: 6.81955 | K73: 3.77129 | O73: 3179.8 | Q73: 5667.75 | S73: 1502.89 | U73: 3.46275 | W73: 32.3678 | Y73: 8.58284 | AA73: 533.429 | AC73: 45.2764 | AE73: 1 | AG73: 7.64297 | AI73: 8.71076 | AK73: 22.5176 | AM73: 28.1973
B74: 42434 | C74: 17.7714 | E74: 0.908632 | G74: 15.1858 | I74: 6.8357 | K74: 3.75879 | O74: 3187.35 | Q74: 5690 | S74: 1513.82 | U74: 3.45575 | W74: 32.507 | Y74: 8.64841 | AA74: 534.57 | AC74: 45.7095 | AE74: 1 | AG74: 7.6609 | AI74: 8.73085 | AK74: 22.543 | AM74: 28.266
B75: 42435 | C75: 17.7711 | E75: 0.908637 | G75: 15.1912 | I75: 6.8357 | K75: 3.75865 | O75: 3187.35 | Q75: 5690 | S75: 1513.87 | U75: 3.45575 | W75: 32.507 | Y75: 8.64874 | AA75: 534.57 | AC75: 45.7095 | AE75: 1 | AG75: 7.6609 | AI75: 8.73085 | AK75: 22.543 | AM75: 28.266
...

Sheet 2026
A1: USD vs ML | B1: https://www.banxico.org.mx/tipcamb/main.do?page=tip&idioma=sp | I1: OANDA | J1: https://fxds-hcc.oanda.com/lang/es# | AJ1: Descargar
B2: MXN | C2: EUR | D2: ARS | E2: BOB | F2: BRL | G2: CLP | H2: COP | I2: PYG | J2: PEN | K2: UYU | L2: CRC | M2: DOP | N2: PAB | O2: GTQ | P2: SVC | Q2: HNL | R2: NIO | S2: TTD | T2: BRL / PYG | U2: BRL / UYU | AK2: EUR | AL2: ARS | AM2: BOB | AN2: BRL | AO2: CLP | AP2: COP | AQ2: PYG | AR2: PEN | AS2: UYU | AT2: CRC | AU2: DOP | AV2: PAB | AW2: GTQ | AX2: SVC | AY2: HNL | AZ2: NIO | BA2: TTD | BB2: PYG | BC2: UYU
B3: =COLUMN() -> 2 | C3: =COLUMN() -> 3 | D3: =COLUMN() -> 4 | E3: =COLUMN() -> 5 | F3: =COLUMN() -> 6 | G3: =COLUMN() -> 7 | H3: =COLUMN() -> 8 | I3: =COLUMN() -> 9 | ... U3: =COLUMN() -> 21 | AJ3: Media del periodo | AK3: 0.917522 | AL3: 978.987 | AM3: 6.91873 | AN3: 5.61667 | AO3: 936.943 | AP3: 4255.66 | AQ3: 7864.68 | AR3: 3.74971 | AS3: 41.6822 | AT3: 516.513 | AU3: 60.3436 | AV3: 1 | AW3: 7.73749 | AX3: 8.75 | AY3: 25.0176 | AZ3: 36.8065 | BA3: 6.78979 | BB3: 1400.53 | BC3: 7.42395
A4: Media del periodo | B4: =ROUND(AVERAGE(B7:B37),4) -> 17.7324 | C4: 0.865015 | D4: 1397.05 | E4: 6.91932 | F4: 5.24293 | G4: 912.198 | H4: 3721.95 | I4: 6499.47 | J4: 3.44532 | K4: 40.0704 | L4: 469.555 | M4: 60.1365 | N4: 1 | O4: 7.66356 | P4: 8.75 | Q4: 26.5084 | R4: 36.7819 | S4: 6.78415 | T4: 1239.74 | U4: 7.64284 | AJ4: Máxima del periodo | AK4: 0.9272 | AL4: 989.34 | AM4: 6.9342 | AN4: 5.77324 | AO4: 961.7 | AP4: 4415.52 | AQ4: 7998.08 | AR4: 3.77248 | AS4: 41.9004 | AT4: 520.17 | AU4: 60.5313 | AV4: 1 | AW4: 7.75574 | AX4: 8.75 | AY4: 25.25 | AZ4: 36.8663 | BA4: 6.80328 | BB4: 1435.28 | BC4: 7.67528
A5: Máxima del periodo | C5: 0.875929 | D5: 1417.76 | E5: 6.93602 | F5: 5.32336 | G5: 929.09 | H5: 3791.23 | I5: 6538.86 | J5: 3.493 | K5: 40.6498 | L5: 477.745 | M5: 61.713 | N5: 1 | O5: 7.68154 | P5: 8.75 | Q5: 26.5752 | R5: 36.8588 | S5: 6.79862 | T5: 1257.32 | U5: 7.78182 | AJ5: Mínima del periodo | AK5: 0.90126 | AL5: 969.266 | AM5: 6.90398 | AN5: 5.43172 | AO5: 901.805 | AP5: 4169.46 | AQ5: 7795.74 | AR5: 3.71668 | AS5: 41.1344 | AT5: 512.438 | AU5: 60.2005 | AV5: 1 | AW5: 7.72233 | AX5: 8.75 | AY5: 24.8448 | AZ5: 36.7384 | BA5: 6.77628 | BB5: 1377.88 | BC5: 7.12504
A6: Mínima del periodo | C6: 0.846509 | D6: 1373.61 | E6: 6.90347 | F6: 5.12972 | G6: 873.674 | H6: 3674.42 | I6: 6438.39 | J6: 3.35502 | K6: 38.3891 | L6: 463.881 | M6: 59.0075 | N6: 1 | O6: 7.63898 | P6: 8.75 | Q6: 26.441 | R6: 36.6834 | S6: 6.76683 | T6: 1213.72 | U6: 7.37555
A7: 46112 | B7: =VLOOKUP(A7,W:X,2,FALSE) -> 18.1033 | C7: 0.869228 | D7: 1391.52 | E7: 6.92307 | F7: 5.2297 | G7: 929.09 | H7: 3674.74 | I7: 6506.32 | J7: 3.493 | K7: 40.6234 | L7: 464.956 | M7: 59.9089 | N7: 1 | O7: 7.65559 | P7: 8.75 | Q7: 26.5752 | R7: 36.7996 | S7: 6.79325 | T7: 1244.12 | U7: 7.76787
A8: =A7-1 -> 46111 | B8: =VLOOKUP(A8,W:X,2,FALSE) -> 18.0667 | C8: 0.870824 | D8: 1390.62 | E8: 6.93232 | F8: 5.24716 | G8: 927.254 | H8: 3674.42 | I8: 6532.8 | J8: 3.48837 | K8: 40.585 | L8: 464.86 | M8: 59.6786 | N8: 1 | O8: 7.66054 | P8: 8.75 | Q8: 26.5676 | R8: 36.8049 | S8: 6.79778 | T8: 1245.02 | U8: 7.73467
A9: =A8-1 -> 46110 | B9: =VLOOKUP(A9,W:X,2,FALSE) -> 17.7957 | C9: 0.868848 | D9: 1385.94 | E9: 6.93554 | F9: 5.24702 | G9: 925.181 | H9: 3676.88 | I9: 6538.44 | J9: 3.46653 | K9: 40.4755 | L9: 464.581 | M9: 59.72 | N9: 1 | O9: 7.65497 | P9: 8.75 | Q9: 26.5206 | R9: 36.7199 | S9: 6.7947 | T9: 1246.12 | U9: 7.71401
A10: =A9-1 -> 46109 | B10: =VLOOKUP(A10,W:X,2,FALSE) -> 17.7957 | C10: 0.8687 | D10: 1385.58 | E10: 6.93602 | F10: 5.24708 | G10: 925.215 | H10: 3676.94 | I10: 6538.86 | J10: 3.4664 | K10: 40.4813 | L10: 464.578 | M10: 59.72 | N10: 1 | O10: 7.65495 | P10: 8.75 | Q10: 26.5205 | R10: 36.7198 | S10: 6.7947 | T10: 1246.2 | U10: 7.71504 | AJ10: 28 de oct. de 2024 | AK10: 0.925259 | AL10: 987.062 | AM10: 6.91332 | AN10: 5.70722 | AO10: 947.671 | AP10: 4337.48 | AQ10: 7998.08 | AR10: 3.76176 | AS10: 41.6176 | AT10: 515.152 | AU10: 60.3466 | AV10: 1 | AW10: 7.73755 | AX10: 8.75 | AY10: 25.217 | AZ10: 36.8385 | BA10: 6.79036 | BB10: 1401.44 | BC10: 7.29227 | BD10: =+C10-AK10 -> -0.056559 | BE10: =+D10-AL10 -> 398.518 | BF10: =+E10-AM10 -> 0.0227 | BG10: =+F10-AN10 -> -0.46014 | BH10: =+G10-AO10 -> -22.456 | BI10: =+H10-AP10 -> -660.54 | BJ10: =+I10-AQ10 -> -1459.22 | BK10: =+J10-AR10 -> -0.29536 | ... BV10: =+U10-BC10 -> 0.42277
A11: =A10-1 -> 46108 | B11: =VLOOKUP(A11,W:X,2,FALSE) -> 17.7957 | C11: 0.867792 | D11: 1373.61 | E11: 6.92506 | F11: 5.24352 | G11: 927.549 | H11: 3684.47 | I11: 6536.68 | J11: 3.46798 | K11: 40.4971 | L11: 463.881 | M11: 59.8451 | N11: 1 | O11: 7.64865 | P11: 8.75 | Q11: 26.5289 | R11: 36.7606 | S11: 6.78762 | T11: 1246.63 | U11: 7.7233 | AJ11: 27 de oct. de 2024 | AK11: 0.926266 | AL11: 985.366 | AM11: 6.92096 | AN11: 5.70761 | AO11: 947.9 | AP11: 4326.18 | AQ11: 7975.63 | AR11: 3.76086 | AS11: 41.6438 | AT11: 515.855 | AU11: 60.2994 | AV11: 1 | AW11: 7.7457 | AX11: 8.75 | AY11: 25.25 | AZ11: 36.836 | BA11: 6.80328 | BB11: 1397.38 | BC11: 7.29622 | BD11: =+C11-AK11 -> -0.058474 | BE11: =+D11-AL11 -> 388.244 | BF11: =+E11-AM11 -> 0.0041 | BG11: =+F11-AN11 -> -0.46409 | BH11: =+G11-AO11 -> -20.351 | BI11: =+H11-AP11 -> -641.71 | BJ11: =+I11-AQ11 -> -1438.95 | BK11: =+J11-AR11 -> -0.29288 | ... BV11: =+U11-BC11 -> 0.42708
A12: =A11-1 -> 46107 | B12: =VLOOKUP(A12,W:X,2,FALSE) -> 17.7548 | C12: 0.865968 | D12: 1373.67 | E12: 6.92672 | F12: 5.23402 | G12: 921.636 | H12: 3695.78 | I12: 6532.82 | J12: 3.46324 | K12: 40.5109 | L12: 464.77 | M12: 60.1714 | N12: 1 | O12: 7.65853 | P12: 8.75 | Q12: 26.5472 | R12: 36.8079 | S12: 6.79862 | T12: 1248.15 | U12: 7.73994 | AJ12: 26 de oct. de 2024 | AK12: 0.926256 | AL12: 985.004 | AM12: 6.92096 | AN12: 5.7076 | AO12: 947.9 | AP12: 4326.18 | AQ12: 7975.63 | AR12: 3.76086 | AS12: 41.6438 | AT12: 515.855 | AU12: 60.2994 | AV12: 1 | AW12: 7.7457 | AX12: 8.75 | AY12: 25.25 | AZ12: 36.836 | BA12: 6.80328 | BB12: 1397.38 | BC12: 7.29622 | BD12: =+C12-AK12 -> -0.060288 | BE12: =+D12-AL12 -> 388.666 | BF12: =+E12-AM12 -> 0.00576 | BG12: =+F12-AN12 -> -0.47358 | BH12: =+G12-AO12 -> -26.264 | BI12: =+H12-AP12 -> -630.4 | BJ12: =+I12-AQ12 -> -1442.81 | BK12: =+J12-AR12 -> -0.29762 | ... BV12: =+U12-BC12 -> 0.44372
A13: =A12-1 -> 46106 | B13: =VLOOKUP(A13,W:X,2,FALSE) -> 17.8047 | C13: 0.86297 | D13: 1388.73 | E13: 6.9158 | F13: 5.23294 | G13: 916.474 | H13: 3703.93 | I13: 6516.53 | J13: 3.45654 | K13: 40.584 | L13: 465.357 | M13: 60.092 | N13: 1 | O13: 7.65048 | P13: 8.75 | Q13: 26.4751 | R13: 36.7642 | S13: 6.79238 | T13: 1245.3 | U13: 7.75552 | AJ13: 25 de oct. de 2024 | AK13: 0.924536 | AL13: 985.187 | AM13: 6.91141 | AN13: 5.68348 | AO13: 947.444 | AP13: 4309.28 | AQ13: 7954.58 | AR13: 3.75282 | AS13: 41.5794 | AT13: 515.112 | AU13: 60.2005 | AV13: 1 | AW13: 7.73438 | AX13: 8.75 | AY13: 25.187 | AZ13: 36.7787 | BA13: 6.79314 | BB13: 1399.6 | BC13: 7.31586 | BD13: =+C13-AK13 -> -0.061566 | BE13: =+D13-AL13 -> 403.543 | BF13: =+E13-AM13 -> 0.00439 | BG13: =+F13-AN13 -> -0.45054 | BH13: =+G13-AO13 -> -30.97 | BI13: =+H13-AP13 -> -605.35 | BJ13: =+I13-AQ13 -> -1438.05 | BK13: =+J13-AR13 -> -0.29628 | ... BV13: =+U13-BC13 -> 0.43966
